Workbook

Sheet Raw Data
A2: Rk | B2: Squad | C2: Attendance | D2: Home | Q2: Away
B3: ▲ | D3: MP | E3: W | F3: D | G3: L | H3: GF | I3: GA | J3: GD | K3: Pts | L3: Pts/MP | M3: xG | N3: xGA | O3: xGD | P3: xGD/90 | Q3: MP | R3: W | S3: D | T3: L | U3: GF | V3: GA | W3: GD | X3: Pts | Y3: Pts/MP | Z3: xG | AA3: xGA | AB3: xGD | AC3: xGD/90
A4: 5 | B4: Arsenal | C4: 59899 | D4: 19 | E4: 14 | F4: 3 | G4: 2 | H4: 42 | I4: 16 | J4: 26 | K4: 45 | L4: 2.37 | M4: 34.6 | N4: 23.5 | O4: 11 | P4: 0.58 | Q4: 19 | R4: 7 | S4: 4 | T4: 8 | U4: 31 | V4: 35 | W4: -4 | X4: 25 | Y4: 1.32 | Z4: 25.5 | AA4: 30.7 | AB4: -5.2 | AC4: -0.27
A5: 14 | B5: Bournemouth | C5: 10532 | D5: 19 | E5: 8 | F5: 5 | G5: 6 | H5: 30 | I5: 25 | J5: 5 | K5: 29 | L5: 1.53 | M5: 27.7 | N5: 25.2 | O5: 2.5 | P5: 0.13 | Q5: 19 | R5: 5 | S5: 1 | T5: 13 | U5: 26 | V5: 45 | W5: -19 | X5: 16 | Y5: 0.84 | Z5: 25.6 | AA5: 32 | AB5: -6.4 | AC5: -0.34
A6: 17 | B6: Brighton | C6: 30426 | D6: 19 | E6: 6 | F6: 5 | G6: 8 | H6: 19 | I6: 28 | J6: -9 | K6: 23 | L6: 1.21 | M6: 19.9 | N6: 24 | O6: -4.1 | P6: -0.22 | Q6: 19 | R6: 3 | S6: 4 | T6: 12 | U6: 16 | V6: 32 | W6: -16 | X6: 13 | Y6: 0.68 | Z6: 15.4 | AA6: 35.1 | AB6: -19.7 | AC6: -1.04
A7: 15 | B7: Burnley | C7: 20534 | D7: 19 | E7: 7 | F7: 2 | G7: 10 | H7: 24 | I7: 32 | J7: -8 | K7: 23 | L7: 1.21 | M7: 25.6 | N7: 26.3 | O7: -0.8 | P7: -0.04 | Q7: 19 | R7: 4 | S7: 5 | T7: 10 | U7: 21 | V7: 36 | W7: -15 | X7: 17 | Y7: 0.89 | Z7: 18.8 | AA7: 35.7 | AB7: -16.9 | AC7: -0.89
A8: 18 | B8: Cardiff City | C8: 31408 | D8: 19 | E8: 6 | F8: 2 | G8: 11 | H8: 21 | I8: 38 | J8: -17 | K8: 20 | L8: 1.05 | M8: 24.6 | N8: 25.5 | O8: -1 | P8: -0.05 | Q8: 19 | R8: 4 | S8: 2 | T8: 13 | U8: 13 | V8: 31 | W8: -18 | X8: 14 | Y8: 0.74 | Z8: 17.8 | AA8: 35.9 | AB8: -18.2 | AC8: -0.96
A9: 3 | B9: Chelsea | C9: 40437 | D9: 19 | E9: 12 | F9: 6 | G9: 1 | H9: 39 | I9: 12 | J9: 27 | K9: 42 | L9: 2.21 | M9: 31 | N9: 14.4 | O9: 16.6 | P9: 0.87 | Q9: 19 | R9: 9 | S9: 3 | T9: 7 | U9: 24 | V9: 27 | W9: -3 | X9: 30 | Y9: 1.58 | Z9: 27.6 | AA9: 22 | AB9: 5.6 | AC9: 0.29
A10: 12 | B10: Crystal Palace | C10: 25455 | D10: 19 | E10: 5 | F10: 5 | G10: 9 | H10: 19 | I10: 23 | J10: -4 | K10: 20 | L10: 1.05 | M10: 28.1 | N10: 23.5 | O10: 4.7 | P10: 0.25 | Q10: 19 | R10: 9 | S10: 2 | T10: 8 | U10: 32 | V10: 30 | W10: 2 | X10: 29 | Y10: 1.53 | Z10: 19.5 | AA10: 26.6 | AB10: -7.2 | AC10: -0.38
A11: 8 | B11: Everton | C11: 39043 | D11: 19 | E11: 10 | F11: 4 | G11: 5 | H11: 30 | I11: 21 | J11: 9 | K11: 34 | L11: 1.79 | M11: 28 | N11: 21.7 | O11: 6.2 | P11: 0.33 | Q11: 19 | R11: 5 | S11: 5 | T11: 9 | U11: 24 | V11: 25 | W11: -1 | X11: 20 | Y11: 1.05 | Z11: 21.7 | AA11: 24 | AB11: -2.3 | AC11: -0.12
A12: 19 | B12: Fulham | C12: 24371 | D12: 19 | E12: 6 | F12: 3 | G12: 10 | H12: 22 | I12: 36 | J12: -14 | K12: 21 | L12: 1.11 | M12: 24 | N12: 27.8 | O12: -3.7 | P12: -0.2 | Q12: 19 | R12: 1 | S12: 2 | T12: 16 | U12: 12 | V12: 45 | W12: -33 | X12: 5 | Y12: 0.26 | Z12: 17.3 | AA12: 40.4 | AB12: -23.1 | AC12: -1.22
A13: 20 | B13: Huddersfield | C13: 23203 | D13: 19 | E13: 2 | F13: 3 | G13: 14 | H13: 10 | I13: 31 | J13: -21 | K13: 9 | L13: 0.47 | M13: 16.2 | N13: 28 | O13: -11.8 | P13: -0.62 | Q13: 19 | R13: 1 | S13: 4 | T13: 14 | U13: 12 | V13: 45 | W13: -33 | X13: 7 | Y13: 0.37 | Z13: 12.6 | AA13: 32.9 | AB13: -20.3 | AC13: -1.07
A14: 9 | B14: Leicester City | C14: 31851 | D14: 19 | E14: 8 | F14: 3 | G14: 8 | H14: 24 | I14: 20 | J14: 4 | K14: 27 | L14: 1.42 | M14: 26.3 | N14: 19.9 | O14: 6.5 | P14: 0.34 | Q14: 19 | R14: 7 | S14: 4 | T14: 8 | U14: 27 | V14: 28 | W14: -1 | X14: 25 | Y14: 1.32 | Z14: 26.1 | AA14: 23.8 | AB14: 2.3 | AC14: 0.12
A15: 2 | B15: Liverpool | C15: 52983 | D15: 19 | E15: 17 | F15: 2 | G15: 0 | H15: 55 | I15: 10 | J15: 45 | K15: 53 | L15: 2.79 | M15: 42.2 | N15: 13.2 | O15: 28.9 | P15: 1.52 | Q15: 19 | R15: 13 | S15: 5 | T15: 1 | U15: 34 | V15: 12 | W15: 22 | X15: 44 | Y15: 2.32 | Z15: 31.6 | AA15: 15.6 | AB15: 16 | AC15: 0.84
... A23: 7 | B23: Wolves | C23: 31030 | D23: 19 | E23: 10 | F23: 4 | G23: 5 | H23: 28 | I23: 21 | J23: 7 | K23: 34 | L23: 1.79 | M23: 31.3 | N23: 18.9 | O23: 12.4 | P23: 0.65 | Q23: 19 | R23: 6 | S23: 5 | T23: 8 | U23: 19 | V23: 25 | W23: -6 | X23: 23 | Y23: 1.21 | Z23: 20.9 | AA23: 23.2 | AB23: -2.3 | AC23: -0.12
A25: Rk | B25: Squad | C25: Attendance | D25: Home | Q25: Away
B26: ▲ | D26: MP | E26: W | F26: D | G26: L | H26: GF | I26: GA | J26: GD | K26: Pts | L26: Pts/MP | M26: xG | N26: xGA | O26: xGD | P26: xGD/90 | Q26: MP | R26: W | S26: D | T26: L | U26: GF | V26: GA | W26: GD | X26: Pts | Y26: Pts/MP | Z26: xG | AA26: xGA | AB26: xGD | AC26: xGD/90
A27: 8 | B27: Arsenal | C27: 632 | D27: 19 | E27: 8 | F27: 4 | G27: 7 | H27: 24 | I27: 21 | J27: 3 | K27: 28 | L27: 1.47 | M27: 23 | N27: 23.2 | O27: -0.2 | P27: -0.01 | Q27: 19 | R27: 10 | S27: 3 | T27: 6 | U27: 31 | V27: 18 | W27: 13 | X27: 33 | Y27: 1.74 | Z27: 28.8 | AA27: 19.8 | AB27: 9 | AC27: 0.47
A28: 11 | B28: Aston Villa | C28: 526 | D28: 19 | E28: 7 | F28: 4 | G28: 8 | H28: 29 | I28: 27 | J28: 2 | K28: 25 | L28: 1.32 | M28: 27.9 | N28: 25.9 | O28: 2 | P28: 0.11 | Q28: 19 | R28: 9 | S28: 3 | T28: 7 | U28: 26 | V28: 19 | W28: 7 | X28: 30 | Y28: 1.58 | Z28: 24.6 | AA28: 25.2 | AB28: -0.6 | AC28: -0.03
A29: 16 | B29: Brighton | C29: 523 | D29: 19 | E29: 4 | F29: 9 | G29: 6 | H29: 22 | I29: 22 | J29: 0 | K29: 21 | L29: 1.11 | M29: 30.6 | N29: 14.2 | O29: 16.4 | P29: 0.86 | Q29: 19 | R29: 5 | S29: 5 | T29: 9 | U29: 18 | V29: 24 | W29: -6 | X29: 20 | Y29: 1.05 | Z29: 20.2 | AA29: 21.1 | AB29: -0.8 | AC29: -0.04
A30: 17 | B30: Burnley | C30: 178 | D30: 19 | E30: 4 | F30: 6 | G30: 9 | H30: 14 | I30: 27 | J30: -13 | K30: 18 | L30: 0.95 | M30: 20.5 | N30: 27.3 | O30: -6.8 | P30: -0.36 | Q30: 19 | R30: 6 | S30: 3 | T30: 10 | U30: 19 | V30: 28 | W30: -9 | X30: 21 | Y30: 1.11 | Z30: 18.8 | AA30: 27.3 | AB30: -8.6 | AC30: -0.45
A31: 4 | B31: Chelsea | C31: 526 | D31: 19 | E31: 9 | F31: 6 | G31: 4 | H31: 31 | I31: 18 | J31: 13 | K31: 33 | L31: 1.74 | M31: 34.1 | N31: 15.2 | O31: 18.9 | P31: 0.99 | Q31: 19 | R31: 10 | S31: 4 | T31: 5 | U31: 27 | V31: 18 | W31: 9 | X31: 34 | Y31: 1.79 | Z31: 28.3 | AA31: 15.1 | AB31: 13.2 | AC31: 0.7
A32: 14 | B32: Crystal Palace | C32: 447 | D32: 19 | E32: 6 | F32: 5 | G32: 8 | H32: 20 | I32: 32 | J32: -12 | K32: 23 | L32: 1.21 | M32: 15.8 | N32: 28.1 | O32: -12.3 | P32: -0.65 | Q32: 19 | R32: 6 | S32: 3 | T32: 10 | U32: 21 | V32: 34 | W32: -13 | X32: 21 | Y32: 1.11 | Z32: 18.3 | AA32: 30.1 | AB32: -11.8 | AC32: -0.62
A33: 10 | B33: Everton | C33: 368 | D33: 19 | E33: 6 | F33: 4 | G33: 9 | H33: 24 | I33: 28 | J33: -4 | K33: 22 | L33: 1.16 | M33: 23.3 | N33: 25.1 | O33: -1.8 | P33: -0.1 | Q33: 19 | R33: 11 | S33: 4 | T33: 4 | U33: 23 | V33: 20 | W33: 3 | X33: 37 | Y33: 1.95 | Z33: 22.4 | AA33: 25 | AB33: -2.6 | AC33: -0.14
A34: 18 | B34: Fulham | C34: 211 | D34: 19 | E34: 2 | F34: 4 | G34: 13 | H34: 9 | I34: 28 | J34: -19 | K34: 10 | L34: 0.53 | M34: 18.7 | N34: 25.9 | O34: -7.2 | P34: -0.38 | Q34: 19 | R34: 3 | S34: 9 | T34: 7 | U34: 18 | V34: 25 | W34: -7 | X34: 18 | Y34: 0.95 | Z34: 21.8 | AA34: 26.7 | AB34: -4.9 | AC34: -0.26
A35: 9 | B35: Leeds United | C35: 421 | D35: 19 | E35: 8 | F35: 5 | G35: 6 | H35: 28 | I35: 21 | J35: 7 | K35: 29 | L35: 1.53 | M35: 30.6 | N35: 22.9 | O35: 7.7 | P35: 0.41 | Q35: 19 | R35: 10 | S35: 0 | T35: 9 | U35: 34 | V35: 33 | W35: 1 | X35: 30 | Y35: 1.58 | Z35: 25 | AA35: 35 | AB35: -10 | AC35: -0.52
A36: 5 | B36: Leicester City | C36: 421 | D36: 19 | E36: 9 | F36: 1 | G36: 9 | H36: 34 | I36: 30 | J36: 4 | K36: 28 | L36: 1.47 | M36: 28.2 | N36: 25.6 | O36: 2.7 | P36: 0.14 | Q36: 19 | R36: 11 | S36: 5 | T36: 3 | U36: 34 | V36: 20 | W36: 14 | X36: 38 | Y36: 2 | Z36: 27.6 | AA36: 20.4 | AB36: 7.2 | AC36: 0.38
A37: 3 | B37: Liverpool | C37: 837 | D37: 19 | E37: 10 | F37: 3 | G37: 6 | H37: 29 | I37: 20 | J37: 9 | K37: 33 | L37: 1.74 | M37: 31.5 | N37: 21.1 | O37: 10.4 | P37: 0.55 | Q37: 19 | R37: 10 | S37: 6 | T37: 3 | U37: 39 | V37: 22 | W37: 17 | X37: 36 | Y37: 1.89 | Z37: 36 | AA37: 21.8 | AB37: 14.1 | AC37: 0.74
A38: 1 | B38: Manchester City | C38: 526 | D38: 19 | E38: 13 | F38: 2 | G38: 4 | H38: 43 | I38: 17 | J38: 26 | K38: 41 | L38: 2.16 | M38: 37.2 | N38: 14.9 | O38: 22.3 | P38: 1.18 | Q38: 19 | R38: 14 | S38: 3 | T38: 2 | U38: 40 | V38: 15 | W38: 25 | X38: 45 | Y38: 2.37 | Z38: 31 | AA38: 15.3 | AB38: 15.7 | AC38: 0.83
... A46: 13 | B46: Wolves | C46: 237 | D46: 19 | E46: 7 | F46: 4 | G46: 8 | H46: 21 | I46: 25 | J46: -4 | K46: 25 | L46: 1.32 | M46: 19.9 | N46: 20.6 | O46: -0.7 | P46: -0.04 | Q46: 19 | R46: 5 | S46: 5 | T46: 9 | U46: 15 | V46: 27 | W46: -12 | X46: 20 | Y46: 1.05 | Z46: 16.6 | AA46: 28.9 | AB46: -12.3 | AC46: -0.65
A48: Rk | B48: Squad | C48: Attendance | D48: Home | Q48: Away
B49: ▲ | D49: MP | E49: W | F49: D | G49: L | H49: GF | I49: GA | J49: GD | K49: Pts | L49: Pts/MP | M49: xG | N49: xGA | O49: xGD | P49: xGD/90 | Q49: MP | R49: W | S49: D | T49: L | U49: GF | V49: GA | W49: GD | X49: Pts | Y49: Pts/MP | Z49: xG | AA49: xGA | AB49: xGD | AC49: xGD/90
A50: 2 | B50: Arsenal | C50: 60236 | D50: 19 | E50: 15 | F50: 2 | G50: 2 | H50: 48 | I50: 16 | J50: 32 | K50: 47 | L50: 2.47 | M50: 43.5 | N50: 13.5 | O50: 30 | P50: 1.58 | Q50: 19 | R50: 13 | S50: 3 | T50: 3 | U50: 43 | V50: 13 | W50: 30 | X50: 42 | Y50: 2.21 | Z50: 32.6 | AA50: 14.5 | AB50: 18.2 | AC50: 0.96
A51: 4 | B51: Aston Villa | C51: 41858 | D51: 19 | E51: 12 | F51: 4 | G51: 3 | H51: 48 | I51: 28 | J51: 20 | K51: 40 | L51: 2.11 | M51: 39 | N51: 26.3 | O51: 12.7 | P51: 0.67 | Q51: 19 | R51: 8 | S51: 4 | T51: 7 | U51: 28 | V51: 33 | W51: -5 | X51: 28 | Y51: 1.47 | Z51: 24.3 | AA51: 33.6 | AB51: -9.3 | AC51: -0.49
A52: 12 | B52: Bournemouth | C52: 11103 | D52: 19 | E52: 7 | F52: 6 | G52: 6 | H52: 27 | I52: 28 | J52: -1 | K52: 27 | L52: 1.42 | M52: 27.4 | N52: 24.3 | O52: 3.1 | P52: 0.17 | Q52: 19 | R52: 6 | S52: 3 | T52: 10 | U52: 27 | V52: 39 | W52: -12 | X52: 21 | Y52: 1.11 | Z52: 28.5 | AA52: 33.8 | AB52: -5.3 | AC52: -0.28
A53: 16 | B53: Brentford | C53: 17082 | D53: 19 | E53: 5 | F53: 7 | G53: 7 | H53: 29 | I53: 34 | J53: -5 | K53: 22 | L53: 1.16 | M53: 30.8 | N53: 29.7 | O53: 1.1 | P53: 0.06 | Q53: 19 | R53: 5 | S53: 2 | T53: 12 | U53: 27 | V53: 31 | W53: -4 | X53: 17 | Y53: 0.89 | Z53: 27.4 | AA53: 26.3 | AB53: 1.2 | AC53: 0.06
A54: 11 | B54: Brighton | C54: 32638 | D54: 19 | E54: 8 | F54: 6 | G54: 5 | H54: 30 | I54: 27 | J54: 3 | K54: 30 | L54: 1.58 | M54: 32.1 | N54: 25.4 | O54: 6.8 | P54: 0.36 | Q54: 19 | R54: 4 | S54: 6 | T54: 9 | U54: 25 | V54: 35 | W54: -10 | X54: 18 | Y54: 0.95 | Z54: 24.7 | AA54: 30.1 | AB54: -5.4 | AC54: -0.28
A55: 19 | B55: Burnley | C55: 21184 | D55: 19 | E55: 2 | F55: 4 | G55: 13 | H55: 19 | I55: 43 | J55: -24 | K55: 10 | L55: 0.53 | M55: 22.6 | N55: 29.1 | O55: -6.5 | P55: -0.34 | Q55: 19 | R55: 3 | S55: 5 | T55: 11 | U55: 22 | V55: 35 | W55: -13 | X55: 14 | Y55: 0.74 | Z55: 18 | AA55: 41.3 | AB55: -23.2 | AC55: -1.22
A56: 6 | B56: Chelsea | C56: 39524 | D56: 19 | E56: 11 | F56: 4 | G56: 4 | H56: 44 | I56: 26 | J56: 18 | K56: 37 | L56: 1.95 | M56: 44.2 | N56: 24.9 | O56: 19.2 | P56: 1.01 | Q56: 19 | R56: 7 | S56: 5 | T56: 7 | U56: 33 | V56: 37 | W56: -4 | X56: 26 | Y56: 1.37 | Z56: 30.3 | AA56: 33.1 | AB56: -2.8 | AC56: -0.15
A57: 10 | B57: Crystal Palace | C57: 24932 | D57: 19 | E57: 8 | F57: 4 | G57: 7 | H57: 37 | I57: 26 | J57: 11 | K57: 28 | L57: 1.47 | M57: 27.3 | N57: 20.9 | O57: 6.5 | P57: 0.34 | Q57: 19 | R57: 5 | S57: 6 | T57: 8 | U57: 20 | V57: 32 | W57: -12 | X57: 21 | Y57: 1.11 | Z57: 21.2 | AA57: 31.1 | AB57: -9.9 | AC57: -0.52
...

Sheet Clean Data
B2: *teams that played in all 3 seasons (14/20)
B4: Squad | C4: 2018-19 | K4: 2020-21 | S4: 2023-24
C5: Attendance | D5: MP | E5: W | F5: WP | G5: Pts/MP | H5: Home GD | I5: Away GD | J5: PG | K5: Attendance | L5: MP | M5: W | N5: WP | O5: Pts/MP | P5: Home GD | Q5: Away GD | R5: PG | S5: Attendance | T5: MP | U5: W | V5: WP | W5: Pts/MP | X5: Home GD | Y5: Away GD | Z5: PG
B6: Arsenal | C6: 59899 | D6: 19 | E6: 14 | F6: ='Clean Data'!E6/'Clean Data'!D6 -> 0.73684211 | G6: 2.37 | H6: 26 | I6: -4 | J6: =H6-I6 -> 30 | K6: 632 | L6: 19 | M6: 8 | N6: ='Clean Data'!M6/'Clean Data'!L6 -> 0.42105263 | O6: 1.47 | P6: 3 | Q6: 13 | R6: =P6-Q6 -> -10 | S6: 60236 | T6: 19 | U6: 15 | V6: ='Clean Data'!U6/'Clean Data'!T6 -> 0.78947368 | W6: 2.47 | X6: 32 | Y6: 30 | Z6: =X6-Y6 -> 2
B7: Brighton | C7: 30426 | D7: 19 | E7: 6 | F7: ='Clean Data'!E7/'Clean Data'!D7 -> 0.31578947 | G7: 1.21 | H7: -9 | I7: -16 | J7: =H7-I7 -> 7 | K7: 523 | L7: 19 | M7: 4 | N7: ='Clean Data'!M7/'Clean Data'!L7 -> 0.21052632 | O7: 1.11 | P7: 0 | Q7: -6 | R7: =P7-Q7 -> 6 | S7: 32638 | T7: 19 | U7: 8 | V7: ='Clean Data'!U7/'Clean Data'!T7 -> 0.42105263 | W7: 1.58 | X7: 3 | Y7: -10 | Z7: =X7-Y7 -> 13
B8: Burnley | C8: 20534 | D8: 19 | E8: 7 | F8: ='Clean Data'!E8/'Clean Data'!D8 -> 0.36842105 | G8: 1.21 | H8: -8 | I8: -15 | J8: =H8-I8 -> 7 | K8: 178 | L8: 19 | M8: 4 | N8: ='Clean Data'!M8/'Clean Data'!L8 -> 0.21052632 | O8: 0.95 | P8: -13 | Q8: -9 | R8: =P8-Q8 -> -4 | S8: 21184 | T8: 19 | U8: 2 | V8: ='Clean Data'!U8/'Clean Data'!T8 -> 0.10526316 | W8: 0.53 | X8: -24 | Y8: -13 | Z8: =X8-Y8 -> -11
B9: Chelsea | C9: 40437 | D9: 19 | E9: 12 | F9: ='Clean Data'!E9/'Clean Data'!D9 -> 0.63157895 | G9: 2.21 | H9: 27 | I9: -3 | J9: =H9-I9 -> 30 | K9: 526 | L9: 19 | M9: 9 | N9: ='Clean Data'!M9/'Clean Data'!L9 -> 0.47368421 | O9: 1.74 | P9: 13 | Q9: 9 | R9: =P9-Q9 -> 4 | S9: 39524 | T9: 19 | U9: 11 | V9: ='Clean Data'!U9/'Clean Data'!T9 -> 0.57894737 | W9: 1.95 | X9: 18 | Y9: -4 | Z9: =X9-Y9 -> 22
B10: Crystal Palace | C10: 25455 | D10: 19 | E10: 5 | F10: ='Clean Data'!E10/'Clean Data'!D10 -> 0.26315789 | G10: 1.05 | H10: -4 | I10: 2 | J10: =H10-I10 -> -6 | K10: 447 | L10: 19 | M10: 6 | N10: ='Clean Data'!M10/'Clean Data'!L10 -> 0.31578947 | O10: 1.21 | P10: -12 | Q10: -13 | R10: =P10-Q10 -> 1 | S10: 24932 | T10: 19 | U10: 8 | V10: ='Clean Data'!U10/'Clean Data'!T10 -> 0.42105263 | W10: 1.47 | X10: 11 | Y10: -12 | Z10: =X10-Y10 -> 23
B11: Everton | C11: 39043 | D11: 19 | E11: 10 | F11: ='Clean Data'!E11/'Clean Data'!D11 -> 0.52631579 | G11: 1.79 | H11: 9 | I11: -1 | J11: =H11-I11 -> 10 | K11: 368 | L11: 19 | M11: 6 | N11: ='Clean Data'!M11/'Clean Data'!L11 -> 0.31578947 | O11: 1.16 | P11: -4 | Q11: 3 | R11: =P11-Q11 -> -7 | S11: 39042 | T11: 19 | U11: 8 | V11: ='Clean Data'!U11/'Clean Data'!T11 -> 0.42105263 | W11: 1.47 | X11: 4 | Y11: -15 | Z11: =X11-Y11 -> 19
B12: Fulham | C12: 24371 | D12: 19 | E12: 6 | F12: ='Clean Data'!E12/'Clean Data'!D12 -> 0.31578947 | G12: 1.11 | H12: -14 | I12: -33 | J12: =H12-I12 -> 19 | K12: 211 | L12: 19 | M12: 2 | N12: ='Clean Data'!M12/'Clean Data'!L12 -> 0.10526316 | O12: 0.53 | P12: -19 | Q12: -7 | R12: =P12-Q12 -> -12 | S12: 24302 | T12: 19 | U12: 9 | V12: ='Clean Data'!U12/'Clean Data'!T12 -> 0.47368421 | W12: 1.53 | X12: 7 | Y12: -13 | Z12: =X12-Y12 -> 20
B13: Liverpool | C13: 52983 | D13: 19 | E13: 17 | F13: ='Clean Data'!E13/'Clean Data'!D13 -> 0.89473684 | G13: 2.79 | H13: 45 | I13: 22 | J13: =H13-I13 -> 23 | K13: 837 | L13: 19 | M13: 10 | N13: ='Clean Data'!M13/'Clean Data'!L13 -> 0.52631579 | O13: 1.74 | P13: 9 | Q13: 17 | R13: =P13-Q13 -> -8 | S13: 55979 | T13: 19 | U13: 15 | V13: ='Clean Data'!U13/'Clean Data'!T13 -> 0.78947368 | W13: 2.53 | X13: 32 | Y13: 13 | Z13: =X13-Y13 -> 19
B14: Manchester City | C14: 54130 | D14: 19 | E14: 18 | F14: ='Clean Data'!E14/'Clean Data'!D14 -> 0.94736842 | G14: 2.84 | H14: 45 | I14: 27 | J14: =H14-I14 -> 18 | K14: 526 | L14: 19 | M14: 13 | N14: ='Clean Data'!M14/'Clean Data'!L14 -> 0.68421053 | O14: 2.16 | P14: 26 | Q14: 25 | R14: =P14-Q14 -> 1 | S14: 53012 | T14: 19 | U14: 14 | V14: ='Clean Data'!U14/'Clean Data'!T14 -> 0.73684211 | W14: 2.47 | X14: 35 | Y14: 27 | Z14: =X14-Y14 -> 8
B15: Manchester Utd | C15: 74498 | D15: 19 | E15: 10 | F15: ='Clean Data'!E15/'Clean Data'!D15 -> 0.52631579 | G15: 1.89 | H15: 8 | I15: 3 | J15: =H15-I15 -> 5 | K15: 526 | L15: 19 | M15: 9 | N15: ='Clean Data'!M15/'Clean Data'!L15 -> 0.47368421 | O15: 1.63 | P15: 10 | Q15: 19 | R15: =P15-Q15 -> -9 | S15: 73533 | T15: 19 | U15: 10 | V15: ='Clean Data'!U15/'Clean Data'!T15 -> 0.52631579 | W15: 1.74 | X15: 3 | Y15: -4 | Z15: =X15-Y15 -> 7
B16: Newcastle Utd | C16: 51121 | D16: 19 | E16: 8 | F16: ='Clean Data'!E16/'Clean Data'!D16 -> 0.42105263 | G16: 1.32 | H16: -1 | I16: -5 | J16: =H16-I16 -> 4 | K16: 526 | L16: 19 | M16: 6 | N16: ='Clean Data'!M16/'Clean Data'!L16 -> 0.31578947 | O16: 1.21 | P16: -7 | Q16: -9 | R16: =P16-Q16 -> 2 | S16: 52125 | T16: 19 | U16: 12 | V16: ='Clean Data'!U16/'Clean Data'!T16 -> 0.63157895 | W16: 2.11 | X16: 27 | Y16: -4 | Z16: =X16-Y16 -> 31
B17: Tottenham | C17: 54216 | D17: 19 | E17: 12 | F17: ='Clean Data'!E17/'Clean Data'!D17 -> 0.63157895 | G17: 2 | H17: 18 | I17: 10 | J17: =H17-I17 -> 8 | K17: 632 | L17: 19 | M17: 10 | N17: ='Clean Data'!M17/'Clean Data'!L17 -> 0.52631579 | O17: 1.74 | P17: 15 | Q17: 8 | R17: =P17-Q17 -> 7 | S17: 61482 | T17: 19 | U17: 13 | V17: ='Clean Data'!U17/'Clean Data'!T17 -> 0.68421053 | W17: 2.05 | X17: 11 | Y17: 2 | Z17: =X17-Y17 -> 9
... B19: Wolves | C19: 31030 | D19: 19 | E19: 10 | F19: ='Clean Data'!E19/'Clean Data'!D19 -> 0.52631579 | G19: 1.79 | H19: 7 | I19: -6 | J19: =H19-I19 -> 13 | K19: 237 | L19: 19 | M19: 7 | N19: ='Clean Data'!M19/'Clean Data'!L19 -> 0.36842105 | O19: 1.32 | P19: -4 | Q19: -12 | R19: =P19-Q19 -> 8 | S19: 31029 | T19: 19 | U19: 8 | V19: ='Clean Data'!U19/'Clean Data'!T19 -> 0.42105263 | W19: 1.42 | X19: -4 | Y19: -11 | Z19: =X19-Y19 -> 7
B22: *all 20 teams per season
B24: 2018-19 | C24: Squad | D24: Attendance | E24: MP | F24: W | G24: WP | H24: Pts/MP | I24: Home GD | J24: Away GD | K24: PG
C25: Arsenal | D25: 59899 | E25: 19 | F25: 14 | G25: ='Clean Data'!F25/'Clean Data'!E25 -> 0.73684211 | H25: 2.37 | I25: 26 | J25: -4 | K25: =I25-J25 -> 30
C26: Bournemouth | D26: 10532 | E26: 19 | F26: 8 | G26: ='Clean Data'!F26/'Clean Data'!E26 -> 0.42105263 | H26: 1.53 | I26: 5 | J26: -19 | K26: =I26-J26 -> 24
C27: Brighton | D27: 30426 | E27: 19 | F27: 6 | G27: ='Clean Data'!F27/'Clean Data'!E27 -> 0.31578947 | H27: 1.21 | I27: -9 | J27: -16 | K27: =I27-J27 -> 7
C28: Burnley | D28: 20534 | E28: 19 | F28: 7 | G28: ='Clean Data'!F28/'Clean Data'!E28 -> 0.36842105 | H28: 1.21 | I28: -8 | J28: -15 | K28: =I28-J28 -> 7
C29: Cardiff City | D29: 31408 | E29: 19 | F29: 6 | G29: ='Clean Data'!F29/'Clean Data'!E29 -> 0.31578947 | H29: 1.05 | I29: -17 | J29: -18 | K29: =I29-J29 -> 1
C30: Chelsea | D30: 40437 | E30: 19 | F30: 12 | G30: ='Clean Data'!F30/'Clean Data'!E30 -> 0.63157895 | H30: 2.21 | I30: 27 | J30: -3 | K30: =I30-J30 -> 30
C31: Crystal Palace | D31: 25455 | E31: 19 | F31: 5 | G31: ='Clean Data'!F31/'Clean Data'!E31 -> 0.26315789 | H31: 1.05 | I31: -4 | J31: 2 | K31: =I31-J31 -> -6
C32: Everton | D32: 39043 | E32: 19 | F32: 10 | G32: ='Clean Data'!F32/'Clean Data'!E32 -> 0.52631579 | H32: 1.79 | I32: 9 | J32: -1 | K32: =I32-J32 -> 10
C33: Fulham | D33: 24371 | E33: 19 | F33: 6 | G33: ='Clean Data'!F33/'Clean Data'!E33 -> 0.31578947 | H33: 1.11 | I33: -14 | J33: -33 | K33: =I33-J33 -> 19
C34: Huddersfield | D34: 23203 | E34: 19 | F34: 2 | G34: ='Clean Data'!F34/'Clean Data'!E34 -> 0.10526316 | H34: 0.47 | I34: -21 | J34: -33 | K34: =I34-J34 -> 12
C35: Leicester City | D35: 31851 | E35: 19 | F35: 8 | G35: ='Clean Data'!F35/'Clean Data'!E35 -> 0.42105263 | H35: 1.42 | I35: 4 | J35: -1 | K35: =I35-J35 -> 5
C36: Liverpool | D36: 52983 | E36: 19 | F36: 17 | G36: ='Clean Data'!F36/'Clean Data'!E36 -> 0.89473684 | H36: 2.79 | I36: 45 | J36: 22 | K36: =I36-J36 -> 23
... C44: Wolves | D44: 31030 | E44: 19 | F44: 10 | G44: ='Clean Data'!F44/'Clean Data'!E44 -> 0.52631579 | H44: 1.79 | I44: 7 | J44: -6 | K44: =I44-J44 -> 13
B46: 2020-21 | C46: Squad | D46: Attendance | E46: MP | F46: W | G46: WP | H46: Pts/MP | I46: Home GD | J46: Away GD | K46: PG
C47: Arsenal | D47: 632 | E47: 19 | F47: 8 | G47: ='Clean Data'!F47/'Clean Data'!E47 -> 0.42105263 | H47: 1.47 | I47: 3 | J47: 13 | K47: =I47-J47 -> -10
C48: Aston Villa | D48: 526 | E48: 19 | F48: 7 | G48: ='Clean Data'!F48/'Clean Data'!E48 -> 0.36842105 | H48: 1.32 | I48: 2 | J48: 7 | K48: =I48-J48 -> -5
C49: Brighton | D49: 523 | E49: 19 | F49: 4 | G49: ='Clean Data'!F49/'Clean Data'!E49 -> 0.21052632 | H49: 1.11 | I49: 0 | J49: -6 | K49: =I49-J49 -> 6
C50: Burnley | D50: 178 | E50: 19 | F50: 4 | G50: ='Clean Data'!F50/'Clean Data'!E50 -> 0.21052632 | H50: 0.95 | I50: -13 | J50: -9 | K50: =I50-J50 -> -4
C51: Chelsea | D51: 526 | E51: 19 | F51: 9 | G51: ='Clean Data'!F51/'Clean Data'!E51 -> 0.47368421 | H51: 1.74 | I51: 13 | J51: 9 | K51: =I51-J51 -> 4
C52: Crystal Palace | D52: 447 | E52: 19 | F52: 6 | G52: ='Clean Data'!F52/'Clean Data'!E52 -> 0.31578947 | H52: 1.21 | I52: -12 | J52: -13 | K52: =I52-J52 -> 1
C53: Everton | D53: 368 | E53: 19 | F53: 6 | G53: ='Clean Data'!F53/'Clean Data'!E53 -> 0.31578947 | H53: 1.16 | I53: -4 | J53: 3 | K53: =I53-J53 -> -7
C54: Fulham | D54: 211 | E54: 19 | F54: 2 | G54: ='Clean Data'!F54/'Clean Data'!E54 -> 0.10526316 | H54: 0.53 | I54: -19 | J54: -7 | K54: =I54-J54 -> -12
...

Sheet Data Dictionary
B2: DATA DICTIONARY
B4: Features | C4: Description | D4: Range
B5: Squad | C5: team name | D5: All Premier League team names
B6: Attendance | C6: Attendance/Game: home attendance per game during that season | D6: (91, 76104)
B7: MP | C7: Matches Played: total home games played by the team that season | D7: 19
B8: W | C8: Wins: total home wins by the team that season | D8: (2, 18)
B9: WP | C9: Win Percentage: how often the team won at home that season (home wins ÷ total home games) | D9: (5.26%, 94.74%)
B10: Pts/MP | C10: Points/Match: home points earned per home games played that season (3 for win, 1 for draw, 0 for loss) | D10: (.47, 2.84)
B11: Home GD | C11: Home Goal Difference: goals a team scores at home vs. concedes (home goals for - home goals against) | D11: (-38, 45)
B12: Away GD | C12: Away Goal Difference: goals a team scores away vs. concedes (away goals for - away goals against) | D12: (-33, 30)
B13: PG | C13: Performance Gap: how much better teams play at home vs away (home goal differential - away goal differential) | D13: (-11, 31)

Sheet EDA
B2: *teams that played in all 3 seasons (14/20)
B4: Attendance | F4: Home GD | J4: Home Win Percentage
B5: 2018-19 | C5: 2020-21 | D5: 2023-24 | F5: 2018-19 | G5: 2020-21 | H5: 2023-24 | J5: 2018-19 | K5: 2020-21 | L5: 2023-24
B6: 59899 | C6: 632 | D6: 60236 | F6: 26 | G6: 3 | H6: 32 | J6: 0.73684211 | K6: 0.42105263 | L6: 0.78947368
B7: 30426 | C7: 523 | D7: 32638 | F7: -9 | G7: 0 | H7: 3 | J7: 0.31578947 | K7: 0.21052632 | L7: 0.42105263
B8: 20534 | C8: 178 | D8: 21184 | F8: -8 | G8: -13 | H8: -24 | J8: 0.36842105 | K8: 0.21052632 | L8: 0.10526316
B9: 40437 | C9: 526 | D9: 39524 | F9: 27 | G9: 13 | H9: 18 | J9: 0.63157895 | K9: 0.47368421 | L9: 0.57894737
B10: 25455 | C10: 447 | D10: 24932 | F10: -4 | G10: -12 | H10: 11 | J10: 0.26315789 | K10: 0.31578947 | L10: 0.42105263
B11: 39043 | C11: 368 | D11: 39042 | F11: 9 | G11: -4 | H11: 4 | J11: 0.52631579 | K11: 0.31578947 | L11: 0.42105263
B12: 24371 | C12: 211 | D12: 24302 | F12: -14 | G12: -19 | H12: 7 | J12: 0.31578947 | K12: 0.10526316 | L12: 0.47368421
B13: 52983 | C13: 837 | D13: 55979 | F13: 45 | G13: 9 | H13: 32 | J13: 0.89473684 | K13: 0.52631579 | L13: 0.78947368
B14: 54130 | C14: 526 | D14: 53012 | F14: 45 | G14: 26 | H14: 35 | J14: 0.94736842 | K14: 0.68421053 | L14: 0.73684211
B15: 74498 | C15: 526 | D15: 73533 | F15: 8 | G15: 10 | H15: 3 | J15: 0.52631579 | K15: 0.47368421 | L15: 0.52631579
B16: 51121 | C16: 526 | D16: 52125 | F16: -1 | G16: -7 | H16: 27 | J16: 0.42105263 | K16: 0.31578947 | L16: 0.63157895
B17: 54216 | C17: 632 | D17: 61482 | F17: 18 | G17: 15 | H17: 11 | J17: 0.63157895 | K17: 0.52631579 | L17: 0.68421053
... B19: 31030 | C19: 237 | D19: 31029 | F19: 7 | G19: -4 | H19: -4 | J19: 0.52631579 | K19: 0.36842105 | L19: 0.42105263
B20: Figure 6 | F20: Figure 8 | J20: Figure 10
B39: Squad | C39: Average Home GD | D39: Average Away GD | G39: Squad | H39: Average Home GD | I39: Average Attendance | M39: Figure 16
B40: Arsenal | C40: 20.333333 | D40: 13 | G40: Arsenal | H40: 20.333333 | I40: 40255.667
B41: Brighton | C41: -2 | D41: -10.666667 | G41: Brighton | H41: -2 | I41: 21195.667 | N41: Average Home GD | O41: Average Away GD
B42: Burnley | C42: -15 | D42: -12.333333 | G42: Burnley | H42: -15 | I42: 13965.333 | M42: 2018-19 | N42: =AVERAGE('[1]Clean Data PL'!H8:H21) -> 11 | O42: =AVERAGE('[1]Clean Data PL'!I8:I21) -> -1.9285714
B43: Chelsea | C43: 19.333333 | D43: 0.66666667 | G43: Chelsea | H43: 19.333333 | I43: 26829 | M43: 2020-21 | N43: =AVERAGE('[1]Clean Data PL'!P8:P21) -> 1.9285714 | O43: =AVERAGE('[1]Clean Data PL'!Q8:Q21) -> 3.0714286
B44: Crystal Palace | C44: -1.6666667 | D44: -7.6666667 | G44: Crystal Palace | H44: -1.6666667 | I44: 16944.667 | M44: 2023-24 | N44: =AVERAGE('[1]Clean Data PL'!X8:X21) -> 11.285714 | O44: =AVERAGE('[1]Clean Data PL'!Y8:Y21) -> -2.2142857
B45: Everton | C45: 3 | D45: -4.3333333 | G45: Everton | H45: 3 | I45: 26151
B46: Fulham | C46: -8.6666667 | D46: -17.666667 | G46: Fulham | H46: -8.6666667 | I46: 16294.667
B47: Liverpool | C47: 28.666667 | D47: 17.333333 | G47: Liverpool | H47: 28.666667 | I47: 36599.667 | N47: Average Home Pts/MP
B48: Manchester City | C48: 35.333333 | D48: 26.333333 | G48: Manchester City | H48: 35.333333 | I48: 35889.333 | M48: 2018-19 | N48: 1.8007143
B49: Manchester Utd | C49: 7 | D49: 6 | G49: Manchester Utd | H49: 7 | I49: 49519 | M49: 2020-21 | N49: 1.4114286
B50: Newcastle Utd | C50: 6.3333333 | D50: -6 | G50: Newcastle Utd | H50: 6.3333333 | I50: 34590.667 | M50: 2023-24 | N50: 1.775
B51: Tottenham | C51: 14.666667 | D51: 6.6666667 | G51: Tottenham | H51: 14.666667 | I51: 38776.667
B52: West Ham | C52: 6 | D52: -6.6666667 | G52: West Ham | H52: 6 | I52: 40511.667 | M52: Figure 18
B53: Wolves | C53: -0.33333333 | D53: -9.6666667 | G53: Wolves | H53: -0.33333333 | I53: 20765.333
B55: Figure 12 | G55: Figure 14

Sheet CP6 Analysis
B2: *14/20 teams | F2: Analysis Spec
B3: Figure 20
B4: Period | C4: Average Home Pts/MP | D4: Change vs 2018-19 | F4: Figure 19
B5: 2018-19 | C5: =AVERAGE('Clean Data'!G6:G19) -> 1.8007143 | D5: =C5-$C$5 -> 0 | F5: Component | G5: Specification
B6: 2020-21 | C6: =AVERAGE('Clean Data'!O6:O19) -> 1.4114286 | D6: =C6-$C$5 -> -0.38928571 | F6: Research Question | G6: Did home field advantage decline during COVID and rebound post COVID?
B7: 2023-24 | C7: =AVERAGE('Clean Data'!W6:W19) -> 1.775 | D7: =C7-$C$5 -> -0.025714286 | F7: Outcome (DV) | G7: Average Home Points Per Match (Pts/MP)
F8: Predictor / Groups (IV) | G8: Season group: Pre COVID (2018-19), COVID (2020-21), Post COVID (2023-24)
F9: Sample | G9: 14 Premier League teams that played all three seasons
F10: Row Definition | G10: one team's home/away results for each season

Sheet CP7 Analysis
B1: Figure 21
B2: Squad | C2: Season | D2: Home Pts/MP | E2: PG | F2: COVID Season | G2: Average Home Attendance | H2: Stable Team | J2: Figure 22 | M2: Figure 23
B3: Arsenal | C3: 2018-19 | D3: 2.37 | E3: 30 | F3: =IF(C3="2020-21",1,0) -> 0 | G3: 59899 | H3: =IF(COUNTIF($B$3:$B$62,B3)=3,1,0) -> 1 | J3: Component | K3: Specification | N3: Question | O3: Method | P3: Sample | Q3: Outcome
B4: Bournemouth | C4: 2018-19 | D4: 1.53 | E4: 24 | F4: =IF(C4="2020-21",1,0) -> 0 | G4: 10532 | H4: =IF(COUNTIF($B$3:$B$62,B4)=3,1,0) -> 0 | J4: Outcome | K4: Home Points Per Match (Pts/MP) | M4: CP6 | N4: What happened on average? | O4: Home Pts/MP group mean comparison | P4: 14 consistent teams | Q4: Home Pts/MP fell by 0.39 during COVID
B5: Brighton | C5: 2018-19 | D5: 1.21 | E5: 7 | F5: =IF(C5="2020-21",1,0) -> 0 | G5: 30426 | H5: =IF(COUNTIF($B$3:$B$62,B5)=3,1,0) -> 1 | J5: Inputs | K5: Average Home Attendance, COVID Season Indicator, Stable Team Indicator | M5: CP7 | N5: Why did it happen & for which teams? | O5: Regression with average attendance and controls | P5: All 20 teams | Q5: Reduced attendance explains much of the COVID season decline
B6: Burnley | C6: 2018-19 | D6: 1.21 | E6: 7 | F6: =IF(C6="2020-21",1,0) -> 0 | G6: 20534 | H6: =IF(COUNTIF($B$3:$B$62,B6)=3,1,0) -> 1 | J6: Sample | K6: All 20 Premier League teams
B7: Cardiff City | C7: 2018-19 | D7: 1.05 | E7: 1 | F7: =IF(C7="2020-21",1,0) -> 0 | G7: 31408 | H7: =IF(COUNTIF($B$3:$B$62,B7)=3,1,0) -> 0 | J7: Row Definition | K7: One team observed in a given season
B8: Chelsea | C8: 2018-19 | D8: 2.21 | E8: 30 | F8: =IF(C8="2020-21",1,0) -> 0 | G8: 40437 | H8: =IF(COUNTIF($B$3:$B$62,B8)=3,1,0) -> 1 | J8: Rule | K8: Estimate the relationship between attendance and home points per match while controlling for season effects
B9: Crystal Palace | C9: 2018-19 | D9: 1.05 | E9: -6 | F9: =IF(C9="2020-21",1,0) -> 0 | G9: 25455 | H9: =IF(COUNTIF($B$3:$B$62,B9)=3,1,0) -> 1 | J9: Expected Direction | K9: Higher attendance associated with higher home performance
B10: Everton | C10: 2018-19 | D10: 1.79 | E10: 10 | F10: =IF(C10="2020-21",1,0) -> 0 | G10: 39043 | H10: =IF(COUNTIF($B$3:$B$62,B10)=3,1,0) -> 1
B11: Fulham | C11: 2018-19 | D11: 1.11 | E11: 19 | F11: =IF(C11="2020-21",1,0) -> 0 | G11: 24371 | H11: =IF(COUNTIF($B$3:$B$62,B11)=3,1,0) -> 1
B12: Huddersfield | C12: 2018-19 | D12: 0.47 | E12: 12 | F12: =IF(C12="2020-21",1,0) -> 0 | G12: 23203 | H12: =IF(COUNTIF($B$3:$B$62,B12)=3,1,0) -> 0
B13: Leicester City | C13: 2018-19 | D13: 1.42 | E13: 5 | F13: =IF(C13="2020-21",1,0) -> 0 | G13: 31851 | H13: =IF(COUNTIF($B$3:$B$62,B13)=3,1,0) -> 0
B14: Liverpool | C14: 2018-19 | D14: 2.79 | E14: 23 | F14: =IF(C14="2020-21",1,0) -> 0 | G14: 52983 | H14: =IF(COUNTIF($B$3:$B$62,B14)=3,1,0) -> 1
B15: Manchester City | C15: 2018-19 | D15: 2.84 | E15: 18 | F15: =IF(C15="2020-21",1,0) -> 0 | G15: 54130 | H15: =IF(COUNTIF($B$3:$B$62,B15)=3,1,0) -> 1
B16: Manchester Utd | C16: 2018-19 | D16: 1.89 | E16: 5 | F16: =IF(C16="2020-21",1,0) -> 0 | G16: 74498 | H16: =IF(COUNTIF($B$3:$B$62,B16)=3,1,0) -> 1
B17: Newcastle Utd | C17: 2018-19 | D17: 1.32 | E17: 4 | F17: =IF(C17="2020-21",1,0) -> 0 | G17: 51121 | H17: =IF(COUNTIF($B$3:$B$62,B17)=3,1,0) -> 1
B18: Southampton | C18: 2018-19 | D18: 1.21 | E18: 14 | F18: =IF(C18="2020-21",1,0) -> 0 | G18: 30139 | H18: =IF(COUNTIF($B$3:$B$62,B18)=3,1,0) -> 0
B19: Tottenham | C19: 2018-19 | D19: 2 | E19: 8 | F19: =IF(C19="2020-21",1,0) -> 0 | G19: 54216 | H19: =IF(COUNTIF($B$3:$B$62,B19)=3,1,0) -> 1
B20: Watford | C20: 2018-19 | D20: 1.42 | E20: 3 | F20: =IF(C20="2020-21",1,0) -> 0 | G20: 20016 | H20: =IF(COUNTIF($B$3:$B$62,B20)=3,1,0) -> 0
B21: West Ham | C21: 2018-19 | D21: 1.63 | E21: 13 | F21: =IF(C21="2020-21",1,0) -> 0 | G21: 58336 | H21: =IF(COUNTIF($B$3:$B$62,B21)=3,1,0) -> 1
... B62: Wolves | C62: 2023-24 | D62: 1.42 | E62: 7 | F62: =IF(C62="2020-21",1,0) -> 0 | G62: 31029 | H62: =IF(COUNTIF($B$3:$B$62,B62)=3,1,0) -> 1

Sheet CP7 Regression
A1: SUMMARY OUTPUT
A3: Regression Statistics
A4: Multiple R | B4: 0.64076941
A5: R Square | B5: 0.41058544
A6: Adjusted R Square | B6: 0.37900966
A7: Standard Error | B7: 0.42919727
A8: Observations | B8: 60
A10: ANOVA
B11: df | C11: SS | D11: MS | E11: F | F11: Significance F
A12: Regression | B12: 3 | C12: 7.1859569 | D12: 2.395319 | E12: 13.003176 | F12: 1.4813272e-06
A13: Residual | B13: 56 | C13: 10.315776 | D13: 0.18421029
A14: Total | B14: 59 | C14: 17.501733
B16: Coefficients | C16: Standard Error | D16: t Stat | E16: P-value | F16: Lower 95% | G16: Upper 95% | H16: Lower 95.0% | I16: Upper 95.0%
A17: Intercept | B17: 0.71489747 | C17: 0.16746186 | D17: 4.2690167 | E17: 7.6590132e-05 | F17: 0.37943105 | G17: 1.0503639 | H17: 0.37943105 | I17: 1.0503639
A18: COVID Season | B18: 0.49788777 | C18: 0.20520427 | D18: 2.4263031 | E18: 0.018498777 | F18: 0.08681421 | G18: 0.90896132 | H18: 0.08681421 | I18: 0.90896132
A19: Average Home Attendance | B19: 1.9721427e-05 | C19: 4.4340075e-06 | D19: 4.4477658 | E19: 4.1660445e-05 | F19: 1.0839043e-05 | G19: 2.8603812e-05 | H19: 1.0839043e-05 | I19: 2.8603812e-05
A20: Stable Team | B20: 0.19228926 | C20: 0.13541722 | D20: 1.4199764 | E20: 0.16115796 | F20: -0.078984029 | G20: 0.46356254 | H20: -0.078984029 | I20: 0.46356254

Sheet PG Regression
A1: SUMMARY OUTPUT
A3: Regression Statistics | D3: When performance gap is used instead of points, the attendance effect remains positive but is weaker and not statistically significant. This suggests that attendance influences match outcomes more consistently than goal margins, which are inherently noisier.
A4: Multiple R | B4: 0.50653809
A5: R Square | B5: 0.25658084
A6: Adjusted R Square | B6: 0.21675481
A7: Standard Error | B7: 10.020448
A8: Observations | B8: 60
A10: ANOVA
B11: df | C11: SS | D11: MS | E11: F | F11: Significance F
A12: Regression | B12: 3 | C12: 1940.6748 | D12: 646.89161 | E12: 6.4425418 | F12: 0.00079657517
A13: Residual | B13: 56 | C13: 5622.9252 | D13: 100.40938
A14: Total | B14: 59 | C14: 7563.6
B16: Coefficients | C16: Standard Error | D16: t Stat | E16: P-value | F16: Lower 95% | G16: Upper 95% | H16: Lower 95.0% | I16: Upper 95.0%
A17: Intercept | B17: 8.4754383 | C17: 3.909724 | D17: 2.1677843 | E17: 0.034441374 | F17: 0.64331993 | G17: 16.307557 | H17: 0.64331993 | I17: 16.307557
A18: COVID Season | B18: -7.6241598 | C18: 4.7908943 | D18: -1.5913855 | E18: 0.11715271 | F18: -17.221474 | G18: 1.9731548 | H18: -17.221474 | I18: 1.9731548
A19: Average Home Attendance | B19: 0.00010744196 | C19: 0.00010352056 | D19: 1.0378804 | E19: 0.30378655 | F19: -9.9934645e-05 | G19: 0.00031481856 | H19: -9.9934645e-05 | I19: 0.00031481856
A20: Stable Team | B20: -0.71560294 | C20: 3.1615793 | D20: -0.22634351 | E20: 0.82175841 | F20: -7.0490073 | G20: 5.6178014 | H20: -7.0490073 | I20: 5.6178014

Sheet CP8 Figure
B3: Figure 24
