Workbook

Sheet Raw Data
A2: Rk | B2: Squad | C2: Attendance | D2: Home | Q2: Away
B3: ▲ | D3: MP | E3: W | F3: D | G3: L | H3: GF | I3: GA | J3: GD | K3: Pts | L3: Pts/MP | M3: xG | N3: xGA | O3: xGD | P3: xGD/90 | Q3: MP | R3: W | S3: D | T3: L | U3: GF | V3: GA | W3: GD | X3: Pts | Y3: Pts/MP | Z3: xG | AA3: xGA | AB3: xGD | AC3: xGD/90
A4: 5 | B4: Arsenal | C4: 59899 | D4: 19 | E4: 14 | F4: 3 | G4: 2 | H4: 42 | I4: 16 | J4: 26 | K4: 45 | L4: 2.37 | M4: 34.6 | N4: 23.5 | O4: 11 | P4: 0.58 | Q4: 19 | R4: 7 | S4: 4 | T4: 8 | U4: 31 | V4: 35 | W4: -4 | X4: 25 | Y4: 1.32 | Z4: 25.5 | AA4: 30.7 | AB4: -5.2 | AC4: -0.27
A5: 14 | B5: Bournemouth | C5: 10532 | D5: 19 | E5: 8 | F5: 5 | G5: 6 | H5: 30 | I5: 25 | J5: 5 | K5: 29 | L5: 1.53 | M5: 27.7 | N5: 25.2 | O5: 2.5 | P5: 0.13 | Q5: 19 | R5: 5 | S5: 1 | T5: 13 | U5: 26 | V5: 45 | W5: -19 | X5: 16 | Y5: 0.84 | Z5: 25.6 | AA5: 32 | AB5: -6.4 | AC5: -0.34
A6: 17 | B6: Brighton | C6: 30426 | D6: 19 | E6: 6 | F6: 5 | G6: 8 | H6: 19 | I6: 28 | J6: -9 | K6: 23 | L6: 1.21 | M6: 19.9 | N6: 24 | O6: -4.1 | P6: -0.22 | Q6: 19 | R6: 3 | S6: 4 | T6: 12 | U6: 16 | V6: 32 | W6: -16 | X6: 13 | Y6: 0.68 | Z6: 15.4 | AA6: 35.1 | AB6: -19.7 | AC6: -1.04
A7: 15 | B7: Burnley | C7: 20534 | D7: 19 | E7: 7 | F7: 2 | G7: 10 | H7: 24 | I7: 32 | J7: -8 | K7: 23 | L7: 1.21 | M7: 25.6 | N7: 26.3 | O7: -0.8 | P7: -0.04 | Q7: 19 | R7: 4 | S7: 5 | T7: 10 | U7: 21 | V7: 36 | W7: -15 | X7: 17 | Y7: 0.89 | Z7: 18.8 | AA7: 35.7 | AB7: -16.9 | AC7: -0.89
A8: 18 | B8: Cardiff City | C8: 31408 | D8: 19 | E8: 6 | F8: 2 | G8: 11 | H8: 21 | I8: 38 | J8: -17 | K8: 20 | L8: 1.05 | M8: 24.6 | N8: 25.5 | O8: -1 | P8: -0.05 | Q8: 19 | R8: 4 | S8: 2 | T8: 13 | U8: 13 | V8: 31 | W8: -18 | X8: 14 | Y8: 0.74 | Z8: 17.8 | AA8: 35.9 | AB8: -18.2 | AC8: -0.96
A9: 3 | B9: Chelsea | C9: 40437 | D9: 19 | E9: 12 | F9: 6 | G9: 1 | H9: 39 | I9: 12 | J9: 27 | K9: 42 | L9: 2.21 | M9: 31 | N9: 14.4 | O9: 16.6 | P9: 0.87 | Q9: 19 | R9: 9 | S9: 3 | T9: 7 | U9: 24 | V9: 27 | W9: -3 | X9: 30 | Y9: 1.58 | Z9: 27.6 | AA9: 22 | AB9: 5.6 | AC9: 0.29
A10: 12 | B10: Crystal Palace | C10: 25455 | D10: 19 | E10: 5 | F10: 5 | G10: 9 | H10: 19 | I10: 23 | J10: -4 | K10: 20 | L10: 1.05 | M10: 28.1 | N10: 23.5 | O10: 4.7 | P10: 0.25 | Q10: 19 | R10: 9 | S10: 2 | T10: 8 | U10: 32 | V10: 30 | W10: 2 | X10: 29 | Y10: 1.53 | Z10: 19.5 | AA10: 26.6 | AB10: -7.2 | AC10: -0.38
A11: 8 | B11: Everton | C11: 39043 | D11: 19 | E11: 10 | F11: 4 | G11: 5 | H11: 30 | I11: 21 | J11: 9 | K11: 34 | L11: 1.79 | M11: 28 | N11: 21.7 | O11: 6.2 | P11: 0.33 | Q11: 19 | R11: 5 | S11: 5 | T11: 9 | U11: 24 | V11: 25 | W11: -1 | X11: 20 | Y11: 1.05 | Z11: 21.7 | AA11: 24 | AB11: -2.3 | AC11: -0.12
A12: 19 | B12: Fulham | C12: 24371 | D12: 19 | E12: 6 | F12: 3 | G12: 10 | H12: 22 | I12: 36 | J12: -14 | K12: 21 | L12: 1.11 | M12: 24 | N12: 27.8 | O12: -3.7 | P12: -0.2 | Q12: 19 | R12: 1 | S12: 2 | T12: 16 | U12: 12 | V12: 45 | W12: -33 | X12: 5 | Y12: 0.26 | Z12: 17.3 | AA12: 40.4 | AB12: -23.1 | AC12: -1.22
A13: 20 | B13: Huddersfield | C13: 23203 | D13: 19 | E13: 2 | F13: 3 | G13: 14 | H13: 10 | I13: 31 | J13: -21 | K13: 9 | L13: 0.47 | M13: 16.2 | N13: 28 | O13: -11.8 | P13: -0.62 | Q13: 19 | R13: 1 | S13: 4 | T13: 14 | U13: 12 | V13: 45 | W13: -33 | X13: 7 | Y13: 0.37 | Z13: 12.6 | AA13: 32.9 | AB13: -20.3 | AC13: -1.07
A14: 9 | B14: Leicester City | C14: 31851 | D14: 19 | E14: 8 | F14: 3 | G14: 8 | H14: 24 | I14: 20 | J14: 4 | K14: 27 | L14: 1.42 | M14: 26.3 | N14: 19.9 | O14: 6.5 | P14: 0.34 | Q14: 19 | R14: 7 | S14: 4 | T14: 8 | U14: 27 | V14: 28 | W14: -1 | X14: 25 | Y14: 1.32 | Z14: 26.1 | AA14: 23.8 | AB14: 2.3 | AC14: 0.12
A15: 2 | B15: Liverpool | C15: 52983 | D15: 19 | E15: 17 | F15: 2 | G15: 0 | H15: 55 | I15: 10 | J15: 45 | K15: 53 | L15: 2.79 | M15: 42.2 | N15: 13.2 | O15: 28.9 | P15: 1.52 | Q15: 19 | R15: 13 | S15: 5 | T15: 1 | U15: 34 | V15: 12 | W15: 22 | X15: 44 | Y15: 2.32 | Z15: 31.6 | AA15: 15.6 | AB15: 16 | AC15: 0.84
... A23: 7 | B23: Wolves | C23: 31030 | D23: 19 | E23: 10 | F23: 4 | G23: 5 | H23: 28 | I23: 21 | J23: 7 | K23: 34 | L23: 1.79 | M23: 31.3 | N23: 18.9 | O23: 12.4 | P23: 0.65 | Q23: 19 | R23: 6 | S23: 5 | T23: 8 | U23: 19 | V23: 25 | W23: -6 | X23: 23 | Y23: 1.21 | Z23: 20.9 | AA23: 23.2 | AB23: -2.3 | AC23: -0.12
A25: Rk | B25: Squad | C25: Attendance | D25: Home | Q25: Away
B26: ▲ | D26: MP | E26: W | F26: D | G26: L | H26: GF | I26: GA | J26: GD | K26: Pts | L26: Pts/MP | M26: xG | N26: xGA | O26: xGD | P26: xGD/90 | Q26: MP | R26: W | S26: D | T26: L | U26: GF | V26: GA | W26: GD | X26: Pts | Y26: Pts/MP | Z26: xG | AA26: xGA | AB26: xGD | AC26: xGD/90
A27: 8 | B27: Arsenal | C27: 632 | D27: 19 | E27: 8 | F27: 4 | G27: 7 | H27: 24 | I27: 21 | J27: 3 | K27: 28 | L27: 1.47 | M27: 23 | N27: 23.2 | O27: -0.2 | P27: -0.01 | Q27: 19 | R27: 10 | S27: 3 | T27: 6 | U27: 31 | V27: 18 | W27: 13 | X27: 33 | Y27: 1.74 | Z27: 28.8 | AA27: 19.8 | AB27: 9 | AC27: 0.47
A28: 11 | B28: Aston Villa | C28: 526 | D28: 19 | E28: 7 | F28: 4 | G28: 8 | H28: 29 | I28: 27 | J28: 2 | K28: 25 | L28: 1.32 | M28: 27.9 | N28: 25.9 | O28: 2 | P28: 0.11 | Q28: 19 | R28: 9 | S28: 3 | T28: 7 | U28: 26 | V28: 19 | W28: 7 | X28: 30 | Y28: 1.58 | Z28: 24.6 | AA28: 25.2 | AB28: -0.6 | AC28: -0.03
A29: 16 | B29: Brighton | C29: 523 | D29: 19 | E29: 4 | F29: 9 | G29: 6 | H29: 22 | I29: 22 | J29: 0 | K29: 21 | L29: 1.11 | M29: 30.6 | N29: 14.2 | O29: 16.4 | P29: 0.86 | Q29: 19 | R29: 5 | S29: 5 | T29: 9 | U29: 18 | V29: 24 | W29: -6 | X29: 20 | Y29: 1.05 | Z29: 20.2 | AA29: 21.1 | AB29: -0.8 | AC29: -0.04
A30: 17 | B30: Burnley | C30: 178 | D30: 19 | E30: 4 | F30: 6 | G30: 9 | H30: 14 | I30: 27 | J30: -13 | K30: 18 | L30: 0.95 | M30: 20.5 | N30: 27.3 | O30: -6.8 | P30: -0.36 | Q30: 19 | R30: 6 | S30: 3 | T30: 10 | U30: 19 | V30: 28 | W30: -9 | X30: 21 | Y30: 1.11 | Z30: 18.8 | AA30: 27.3 | AB30: -8.6 | AC30: -0.45
A31: 4 | B31: Chelsea | C31: 526 | D31: 19 | E31: 9 | F31: 6 | G31: 4 | H31: 31 | I31: 18 | J31: 13 | K31: 33 | L31: 1.74 | M31: 34.1 | N31: 15.2 | O31: 18.9 | P31: 0.99 | Q31: 19 | R31: 10 | S31: 4 | T31: 5 | U31: 27 | V31: 18 | W31: 9 | X31: 34 | Y31: 1.79 | Z31: 28.3 | AA31: 15.1 | AB31: 13.2 | AC31: 0.7
A32: 14 | B32: Crystal Palace | C32: 447 | D32: 19 | E32: 6 | F32: 5 | G32: 8 | H32: 20 | I32: 32 | J32: -12 | K32: 23 | L32: 1.21 | M32: 15.8 | N32: 28.1 | O32: -12.3 | P32: -0.65 | Q32: 19 | R32: 6 | S32: 3 | T32: 10 | U32: 21 | V32: 34 | W32: -13 | X32: 21 | Y32: 1.11 | Z32: 18.3 | AA32: 30.1 | AB32: -11.8 | AC32: -0.62
A33: 10 | B33: Everton | C33: 368 | D33: 19 | E33: 6 | F33: 4 | G33: 9 | H33: 24 | I33: 28 | J33: -4 | K33: 22 | L33: 1.16 | M33: 23.3 | N33: 25.1 | O33: -1.8 | P33: -0.1 | Q33: 19 | R33: 11 | S33: 4 | T33: 4 | U33: 23 | V33: 20 | W33: 3 | X33: 37 | Y33: 1.95 | Z33: 22.4 | AA33: 25 | AB33: -2.6 | AC33: -0.14
A34: 18 | B34: Fulham | C34: 211 | D34: 19 | E34: 2 | F34: 4 | G34: 13 | H34: 9 | I34: 28 | J34: -19 | K34: 10 | L34: 0.53 | M34: 18.7 | N34: 25.9 | O34: -7.2 | P34: -0.38 | Q34: 19 | R34: 3 | S34: 9 | T34: 7 | U34: 18 | V34: 25 | W34: -7 | X34: 18 | Y34: 0.95 | Z34: 21.8 | AA34: 26.7 | AB34: -4.9 | AC34: -0.26
A35: 9 | B35: Leeds United | C35: 421 | D35: 19 | E35: 8 | F35: 5 | G35: 6 | H35: 28 | I35: 21 | J35: 7 | K35: 29 | L35: 1.53 | M35: 30.6 | N35: 22.9 | O35: 7.7 | P35: 0.41 | Q35: 19 | R35: 10 | S35: 0 | T35: 9 | U35: 34 | V35: 33 | W35: 1 | X35: 30 | Y35: 1.58 | Z35: 25 | AA35: 35 | AB35: -10 | AC35: -0.52
A36: 5 | B36: Leicester City | C36: 421 | D36: 19 | E36: 9 | F36: 1 | G36: 9 | H36: 34 | I36: 30 | J36: 4 | K36: 28 | L36: 1.47 | M36: 28.2 | N36: 25.6 | O36: 2.7 | P36: 0.14 | Q36: 19 | R36: 11 | S36: 5 | T36: 3 | U36: 34 | V36: 20 | W36: 14 | X36: 38 | Y36: 2 | Z36: 27.6 | AA36: 20.4 | AB36: 7.2 | AC36: 0.38
A37: 3 | B37: Liverpool | C37: 837 | D37: 19 | E37: 10 | F37: 3 | G37: 6 | H37: 29 | I37: 20 | J37: 9 | K37: 33 | L37: 1.74 | M37: 31.5 | N37: 21.1 | O37: 10.4 | P37: 0.55 | Q37: 19 | R37: 10 | S37: 6 | T37: 3 | U37: 39 | V37: 22 | W37: 17 | X37: 36 | Y37: 1.89 | Z37: 36 | AA37: 21.8 | AB37: 14.1 | AC37: 0.74
A38: 1 | B38: Manchester City | C38: 526 | D38: 19 | E38: 13 | F38: 2 | G38: 4 | H38: 43 | I38: 17 | J38: 26 | K38: 41 | L38: 2.16 | M38: 37.2 | N38: 14.9 | O38: 22.3 | P38: 1.18 | Q38: 19 | R38: 14 | S38: 3 | T38: 2 | U38: 40 | V38: 15 | W38: 25 | X38: 45 | Y38: 2.37 | Z38: 31 | AA38: 15.3 | AB38: 15.7 | AC38: 0.83
... A46: 13 | B46: Wolves | C46: 237 | D46: 19 | E46: 7 | F46: 4 | G46: 8 | H46: 21 | I46: 25 | J46: -4 | K46: 25 | L46: 1.32 | M46: 19.9 | N46: 20.6 | O46: -0.7 | P46: -0.04 | Q46: 19 | R46: 5 | S46: 5 | T46: 9 | U46: 15 | V46: 27 | W46: -12 | X46: 20 | Y46: 1.05 | Z46: 16.6 | AA46: 28.9 | AB46: -12.3 | AC46: -0.65
A48: Rk | B48: Squad | C48: Attendance | D48: Home | Q48: Away
B49: ▲ | D49: MP | E49: W | F49: D | G49: L | H49: GF | I49: GA | J49: GD | K49: Pts | L49: Pts/MP | M49: xG | N49: xGA | O49: xGD | P49: xGD/90 | Q49: MP | R49: W | S49: D | T49: L | U49: GF | V49: GA | W49: GD | X49: Pts | Y49: Pts/MP | Z49: xG | AA49: xGA | AB49: xGD | AC49: xGD/90
A50: 2 | B50: Arsenal | C50: 60236 | D50: 19 | E50: 15 | F50: 2 | G50: 2 | H50: 48 | I50: 16 | J50: 32 | K50: 47 | L50: 2.47 | M50: 43.5 | N50: 13.5 | O50: 30 | P50: 1.58 | Q50: 19 | R50: 13 | S50: 3 | T50: 3 | U50: 43 | V50: 13 | W50: 30 | X50: 42 | Y50: 2.21 | Z50: 32.6 | AA50: 14.5 | AB50: 18.2 | AC50: 0.96
A51: 4 | B51: Aston Villa | C51: 41858 | D51: 19 | E51: 12 | F51: 4 | G51: 3 | H51: 48 | I51: 28 | J51: 20 | K51: 40 | L51: 2.11 | M51: 39 | N51: 26.3 | O51: 12.7 | P51: 0.67 | Q51: 19 | R51: 8 | S51: 4 | T51: 7 | U51: 28 | V51: 33 | W51: -5 | X51: 28 | Y51: 1.47 | Z51: 24.3 | AA51: 33.6 | AB51: -9.3 | AC51: -0.49
A52: 12 | B52: Bournemouth | C52: 11103 | D52: 19 | E52: 7 | F52: 6 | G52: 6 | H52: 27 | I52: 28 | J52: -1 | K52: 27 | L52: 1.42 | M52: 27.4 | N52: 24.3 | O52: 3.1 | P52: 0.17 | Q52: 19 | R52: 6 | S52: 3 | T52: 10 | U52: 27 | V52: 39 | W52: -12 | X52: 21 | Y52: 1.11 | Z52: 28.5 | AA52: 33.8 | AB52: -5.3 | AC52: -0.28
A53: 16 | B53: Brentford | C53: 17082 | D53: 19 | E53: 5 | F53: 7 | G53: 7 | H53: 29 | I53: 34 | J53: -5 | K53: 22 | L53: 1.16 | M53: 30.8 | N53: 29.7 | O53: 1.1 | P53: 0.06 | Q53: 19 | R53: 5 | S53: 2 | T53: 12 | U53: 27 | V53: 31 | W53: -4 | X53: 17 | Y53: 0.89 | Z53: 27.4 | AA53: 26.3 | AB53: 1.2 | AC53: 0.06
A54: 11 | B54: Brighton | C54: 32638 | D54: 19 | E54: 8 | F54: 6 | G54: 5 | H54: 30 | I54: 27 | J54: 3 | K54: 30 | L54: 1.58 | M54: 32.1 | N54: 25.4 | O54: 6.8 | P54: 0.36 | Q54: 19 | R54: 4 | S54: 6 | T54: 9 | U54: 25 | V54: 35 | W54: -10 | X54: 18 | Y54: 0.95 | Z54: 24.7 | AA54: 30.1 | AB54: -5.4 | AC54: -0.28
A55: 19 | B55: Burnley | C55: 21184 | D55: 19 | E55: 2 | F55: 4 | G55: 13 | H55: 19 | I55: 43 | J55: -24 | K55: 10 | L55: 0.53 | M55: 22.6 | N55: 29.1 | O55: -6.5 | P55: -0.34 | Q55: 19 | R55: 3 | S55: 5 | T55: 11 | U55: 22 | V55: 35 | W55: -13 | X55: 14 | Y55: 0.74 | Z55: 18 | AA55: 41.3 | AB55: -23.2 | AC55: -1.22
A56: 6 | B56: Chelsea | C56: 39524 | D56: 19 | E56: 11 | F56: 4 | G56: 4 | H56: 44 | I56: 26 | J56: 18 | K56: 37 | L56: 1.95 | M56: 44.2 | N56: 24.9 | O56: 19.2 | P56: 1.01 | Q56: 19 | R56: 7 | S56: 5 | T56: 7 | U56: 33 | V56: 37 | W56: -4 | X56: 26 | Y56: 1.37 | Z56: 30.3 | AA56: 33.1 | AB56: -2.8 | AC56: -0.15
A57: 10 | B57: Crystal Palace | C57: 24932 | D57: 19 | E57: 8 | F57: 4 | G57: 7 | H57: 37 | I57: 26 | J57: 11 | K57: 28 | L57: 1.47 | M57: 27.3 | N57: 20.9 | O57: 6.5 | P57: 0.34 | Q57: 19 | R57: 5 | S57: 6 | T57: 8 | U57: 20 | V57: 32 | W57: -12 | X57: 21 | Y57: 1.11 | Z57: 21.2 | AA57: 31.1 | AB57: -9.9 | AC57: -0.52
...

Sheet Clean Data LL
B2: LA LIGA
B4: *teams that played in all 3 seasons (12/20)
B6: Squad | C6: 2018-19 | K6: 2020-21 | S6: 2023-24
C7: Attendance | D7: MP | E7: W | F7: WP | G7: Pts/MP | H7: Home GD | I7: Away GD | J7: PG | K7: Attendance | L7: MP | M7: W | N7: WP | O7: Pts/MP | P7: Home GD | Q7: Away GD | R7: PG | S7: Attendance | T7: MP | U7: W | V7: WP | W7: Pts/MP | X7: Home GD | Y7: Away GD | Z7: PG
B8: Alavés | C8: 17295 | D8: 19 | E8: 7 | F8: ='Clean Data LL'!E8/'Clean Data LL'!D8 -> 0.36842105 | G8: 1.53 | H8: 0 | I8: -11 | J8: =H8-I8 -> 11 | L8: 19 | M8: 6 | N8: ='Clean Data LL'!M8/'Clean Data LL'!L8 -> 0.31578947 | O8: 1.26 | P8: -4 | Q8: -17 | R8: =P8-Q8 -> 13 | S8: 17391 | T8: 19 | U8: 9 | V8: ='Clean Data LL'!U8/'Clean Data LL'!T8 -> 0.47368421 | W8: 1.63 | X8: 4 | Y8: -14 | Z8: =X8-Y8 -> 18
B9: Athletic Club | C9: 40664 | D9: 19 | E9: 9 | F9: ='Clean Data LL'!E9/'Clean Data LL'!D9 -> 0.47368421 | G9: 1.84 | H9: 7 | I9: -11 | J9: =H9-I9 -> 18 | L9: 19 | M9: 8 | N9: ='Clean Data LL'!M9/'Clean Data LL'!L9 -> 0.42105263 | O9: 1.58 | P9: 10 | Q9: -6 | R9: =P9-Q9 -> 16 | S9: 46112 | T9: 19 | U9: 12 | V9: ='Clean Data LL'!U9/'Clean Data LL'!T9 -> 0.63157895 | W9: 2.21 | X9: 24 | Y9: 0 | Z9: =X9-Y9 -> 24
B10: Atlético Madrid | C10: 56216 | D10: 19 | E10: 15 | F10: ='Clean Data LL'!E10/'Clean Data LL'!D10 -> 0.78947368 | G10: 2.53 | H10: 22 | I10: 4 | J10: =H10-I10 -> 18 | L10: 19 | M10: 15 | N10: ='Clean Data LL'!M10/'Clean Data LL'!L10 -> 0.78947368 | O10: 2.53 | P10: 30 | Q10: 12 | R10: =P10-Q10 -> 18 | S10: 59121 | T10: 19 | U10: 16 | V10: ='Clean Data LL'!U10/'Clean Data LL'!T10 -> 0.84210526 | W10: 2.58 | X10: 20 | Y10: 7 | Z10: =X10-Y10 -> 13
B11: Barcelona | C11: 76104 | D11: 19 | E11: 15 | F11: ='Clean Data LL'!E11/'Clean Data LL'!D11 -> 0.78947368 | G11: 2.53 | H11: 34 | I11: 20 | J11: =H11-I11 -> 14 | L11: 19 | M11: 11 | N11: ='Clean Data LL'!M11/'Clean Data LL'!L11 -> 0.57894737 | O11: 2 | P11: 24 | Q11: 23 | R11: =P11-Q11 -> 1 | S11: 39846 | T11: 19 | U11: 15 | V11: ='Clean Data LL'!U11/'Clean Data LL'!T11 -> 0.78947368 | W11: 2.42 | X11: 22 | Y11: 13 | Z11: =X11-Y11 -> 9
B12: Betis | C12: 44525 | D12: 19 | E12: 8 | F12: ='Clean Data LL'!E12/'Clean Data LL'!D12 -> 0.42105263 | G12: 1.53 | H12: -1 | I12: -7 | J12: =H12-I12 -> 6 | L12: 19 | M12: 10 | N12: ='Clean Data LL'!M12/'Clean Data LL'!L12 -> 0.52631579 | O12: 1.84 | P12: 6 | Q12: -6 | R12: =P12-Q12 -> 12 | S12: 51259 | T12: 19 | U12: 9 | V12: ='Clean Data LL'!U12/'Clean Data LL'!T12 -> 0.47368421 | W12: 1.79 | X12: 8 | Y12: -5 | Z12: =X12-Y12 -> 13
B13: Celta Vigo | C13: 17603 | D13: 19 | E13: 8 | F13: ='Clean Data LL'!E13/'Clean Data LL'!D13 -> 0.42105263 | G13: 1.53 | H13: 6 | I13: -15 | J13: =H13-I13 -> 21 | K13: 91 | L13: 19 | M13: 9 | N13: ='Clean Data LL'!M13/'Clean Data LL'!L13 -> 0.47368421 | O13: 1.58 | P13: 0 | Q13: -2 | R13: =P13-Q13 -> 2 | S13: 20039 | T13: 19 | U13: 6 | V13: ='Clean Data LL'!U13/'Clean Data LL'!T13 -> 0.31578947 | W13: 1.26 | X13: -2 | Y13: -9 | Z13: =X13-Y13 -> 7
B14: Getafe | C14: 11000 | D14: 19 | E14: 11 | F14: ='Clean Data LL'!E14/'Clean Data LL'!D14 -> 0.57894737 | G14: 1.89 | H14: 15 | I14: -2 | J14: =H14-I14 -> 17 | L14: 19 | M14: 6 | N14: ='Clean Data LL'!M14/'Clean Data LL'!L14 -> 0.31578947 | O14: 1.26 | P14: 2 | Q14: -17 | R14: =P14-Q14 -> 19 | S14: 11456 | T14: 19 | U14: 8 | V14: ='Clean Data LL'!U14/'Clean Data LL'!T14 -> 0.42105263 | W14: 1.53 | X14: -2 | Y14: -10 | Z14: =X14-Y14 -> 8
B15: Real Madrid | C15: 61040 | D15: 19 | E15: 13 | F15: ='Clean Data LL'!E15/'Clean Data LL'!D15 -> 0.68421053 | G15: 2.11 | H15: 17 | I15: 0 | J15: =H15-I15 -> 17 | L15: 19 | M15: 13 | N15: ='Clean Data LL'!M15/'Clean Data LL'!L15 -> 0.68421053 | O15: 2.21 | P15: 20 | Q15: 19 | R15: =P15-Q15 -> 1 | S15: 72061 | T15: 19 | U15: 16 | V15: ='Clean Data LL'!U15/'Clean Data LL'!T15 -> 0.84210526 | W15: 2.68 | X15: 39 | Y15: 22 | Z15: =X15-Y15 -> 17
B16: Real Sociedad | C16: 22310 | D16: 19 | E16: 7 | F16: ='Clean Data LL'!E16/'Clean Data LL'!D16 -> 0.36842105 | G16: 1.42 | H16: 3 | I16: -4 | J16: =H16-I16 -> 7 | L16: 19 | M16: 9 | N16: ='Clean Data LL'!M16/'Clean Data LL'!L16 -> 0.47368421 | O16: 1.74 | P16: 13 | Q16: 8 | R16: =P16-Q16 -> 5 | S16: 31710 | T16: 19 | U16: 8 | V16: ='Clean Data LL'!U16/'Clean Data LL'!T16 -> 0.42105263 | W16: 1.58 | X16: 6 | Y16: 6 | Z16: =X16-Y16 -> 0
B17: Sevilla | C17: 35993 | D17: 19 | E17: 12 | F17: ='Clean Data LL'!E17/'Clean Data LL'!D17 -> 0.63157895 | G17: 2.05 | H17: 19 | I17: -4 | J17: =H17-I17 -> 23 | L17: 19 | M17: 14 | N17: ='Clean Data LL'!M17/'Clean Data LL'!L17 -> 0.73684211 | O17: 2.26 | P17: 16 | Q17: 4 | R17: =P17-Q17 -> 12 | S17: 34984 | T17: 19 | U17: 6 | V17: ='Clean Data LL'!U17/'Clean Data LL'!T17 -> 0.31578947 | W17: 1.21 | X17: 0 | Y17: -6 | Z17: =X17-Y17 -> 6
B18: Valencia | C18: 39504 | D18: 19 | E18: 7 | F18: ='Clean Data LL'!E18/'Clean Data LL'!D18 -> 0.36842105 | G18: 1.63 | H18: 12 | I18: 4 | J18: =H18-I18 -> 8 | K18: 142 | L18: 19 | M18: 8 | N18: ='Clean Data LL'!M18/'Clean Data LL'!L18 -> 0.42105263 | O18: 1.63 | P18: 11 | Q18: -14 | R18: =P18-Q18 -> 25 | S18: 43420 | T18: 19 | U18: 8 | V18: ='Clean Data LL'!U18/'Clean Data LL'!T18 -> 0.42105263 | W18: 1.58 | X18: 6 | Y18: -11 | Z18: =X18-Y18 -> 17
B19: Villarreal | C19: 16732 | D19: 19 | E19: 5 | F19: ='Clean Data LL'!E19/'Clean Data LL'!D19 -> 0.26315789 | G19: 1.21 | H19: 2 | I19: -5 | J19: =H19-I19 -> 7 | K19: 253 | L19: 19 | M19: 8 | N19: ='Clean Data LL'!M19/'Clean Data LL'!L19 -> 0.42105263 | O19: 1.58 | P19: 6 | Q19: 10 | R19: =P19-Q19 -> -4 | S19: 17957 | T19: 19 | U19: 7 | V19: ='Clean Data LL'!U19/'Clean Data LL'!T19 -> 0.36842105 | W19: 1.37 | X19: 4 | Y19: -4 | Z19: =X19-Y19 -> 8
B24: *all 20 teams per season
B26: 2018-19 | C26: Squad | D26: Attendance | E26: MP | F26: W | G26: WP | H26: Pts/MP | I26: Home GD | J26: Away GD | K26: PG
C27: Alavés | D27: 17295 | E27: 19 | F27: 7 | G27: ='Clean Data LL'!F27/'Clean Data LL'!E27 -> 0.36842105 | H27: 1.53 | I27: 0 | J27: -11 | K27: =I27-J27 -> 11
C28: Athletic Club | D28: 40664 | E28: 19 | F28: 9 | G28: ='Clean Data LL'!F28/'Clean Data LL'!E28 -> 0.47368421 | H28: 1.84 | I28: 7 | J28: -11 | K28: =I28-J28 -> 18
C29: Atlético Madrid | D29: 56216 | E29: 19 | F29: 15 | G29: ='Clean Data LL'!F29/'Clean Data LL'!E29 -> 0.78947368 | H29: 2.53 | I29: 22 | J29: 4 | K29: =I29-J29 -> 18
C30: Barcelona | D30: 76104 | E30: 19 | F30: 15 | G30: ='Clean Data LL'!F30/'Clean Data LL'!E30 -> 0.78947368 | H30: 2.53 | I30: 34 | J30: 20 | K30: =I30-J30 -> 14
C31: Betis | D31: 44525 | E31: 19 | F31: 8 | G31: ='Clean Data LL'!F31/'Clean Data LL'!E31 -> 0.42105263 | H31: 1.53 | I31: -1 | J31: -7 | K31: =I31-J31 -> 6
C32: Celta Vigo | D32: 17603 | E32: 19 | F32: 8 | G32: ='Clean Data LL'!F32/'Clean Data LL'!E32 -> 0.42105263 | H32: 1.53 | I32: 6 | J32: -15 | K32: =I32-J32 -> 21
C33: Eibar | D33: 4896 | E33: 19 | F33: 9 | G33: ='Clean Data LL'!F33/'Clean Data LL'!E33 -> 0.47368421 | H33: 1.74 | I33: 10 | J33: -14 | K33: =I33-J33 -> 24
C34: Espanyol | D34: 19388 | E34: 19 | F34: 11 | G34: ='Clean Data LL'!F34/'Clean Data LL'!E34 -> 0.57894737 | H34: 1.89 | I34: 6 | J34: -8 | K34: =I34-J34 -> 14
C35: Getafe | D35: 11000 | E35: 19 | F35: 11 | G35: ='Clean Data LL'!F35/'Clean Data LL'!E35 -> 0.57894737 | H35: 1.89 | I35: 15 | J35: -2 | K35: =I35-J35 -> 17
C36: Girona | D36: 10948 | E36: 19 | F36: 3 | G36: ='Clean Data LL'!F36/'Clean Data LL'!E36 -> 0.15789474 | H36: 0.79 | I36: -11 | J36: -5 | K36: =I36-J36 -> -6
C37: Huesca | D37: 6605 | E37: 19 | F37: 5 | G37: ='Clean Data LL'!F37/'Clean Data LL'!E37 -> 0.26315789 | H37: 1.11 | I37: -6 | J37: -16 | K37: =I37-J37 -> 10
C38: Leganés | D38: 10416 | E38: 19 | F38: 7 | G38: ='Clean Data LL'!F38/'Clean Data LL'!E38 -> 0.36842105 | H38: 1.53 | I38: 3 | J38: -9 | K38: =I38-J38 -> 12
... C46: Villarreal | D46: 16732 | E46: 19 | F46: 5 | G46: ='Clean Data LL'!F46/'Clean Data LL'!E46 -> 0.26315789 | H46: 1.21 | I46: 2 | J46: -5 | K46: =I46-J46 -> 7
B48: 2020-21 | C48: Squad | D48: Attendance | E48: MP | F48: W | G48: WP | H48: Pts/MP | I48: Home GD | J48: Away GD | K48: PG
C49: Alavés | E49: 19 | F49: 6 | G49: ='Clean Data LL'!F49/'Clean Data LL'!E49 -> 0.31578947 | H49: 1.26 | I49: -4 | J49: -17 | K49: =I49-J49 -> 13
C50: Athletic Club | E50: 19 | F50: 8 | G50: ='Clean Data LL'!F50/'Clean Data LL'!E50 -> 0.42105263 | H50: 1.58 | I50: 10 | J50: -6 | K50: =I50-J50 -> 16
C51: Atlético Madrid | E51: 19 | F51: 15 | G51: ='Clean Data LL'!F51/'Clean Data LL'!E51 -> 0.78947368 | H51: 2.53 | I51: 30 | J51: 12 | K51: =I51-J51 -> 18
C52: Barcelona | E52: 19 | F52: 11 | G52: ='Clean Data LL'!F52/'Clean Data LL'!E52 -> 0.57894737 | H52: 2 | I52: 24 | J52: 23 | K52: =I52-J52 -> 1
C53: Betis | E53: 19 | F53: 10 | G53: ='Clean Data LL'!F53/'Clean Data LL'!E53 -> 0.52631579 | H53: 1.84 | I53: 6 | J53: -6 | K53: =I53-J53 -> 12
C54: Cádiz | E54: 19 | F54: 5 | G54: ='Clean Data LL'!F54/'Clean Data LL'!E54 -> 0.26315789 | H54: 1.05 | I54: -13 | J54: -9 | K54: =I54-J54 -> -4
C55: Celta Vigo | D55: 91 | E55: 19 | F55: 9 | G55: ='Clean Data LL'!F55/'Clean Data LL'!E55 -> 0.47368421 | H55: 1.58 | I55: 0 | J55: -2 | K55: =I55-J55 -> 2
C56: Eibar | E56: 19 | F56: 2 | G56: ='Clean Data LL'!F56/'Clean Data LL'!E56 -> 0.10526316 | H56: 0.68 | I56: -9 | J56: -14 | K56: =I56-J56 -> 5
...

Sheet Clean Data PL
B2: PREMIER LEAGUE
B4: *teams that played in all 3 seasons (14/20)
B6: Squad | C6: 2018-19 | K6: 2020-21 | S6: 2023-24
C7: Attendance | D7: MP | E7: W | F7: WP | G7: Pts/MP | H7: Home GD | I7: Away GD | J7: PG | K7: Attendance | L7: MP | M7: W | N7: WP | O7: Pts/MP | P7: Home GD | Q7: Away GD | R7: PG | S7: Attendance | T7: MP | U7: W | V7: WP | W7: Pts/MP | X7: Home GD | Y7: Away GD | Z7: PG
B8: Arsenal | C8: 59899 | D8: 19 | E8: 14 | F8: ='Clean Data PL'!E8/'Clean Data PL'!D8 -> 0.73684211 | G8: 2.37 | H8: 26 | I8: -4 | J8: =H8-I8 -> 30 | K8: 632 | L8: 19 | M8: 8 | N8: ='Clean Data PL'!M8/'Clean Data PL'!L8 -> 0.42105263 | O8: 1.47 | P8: 3 | Q8: 13 | R8: =P8-Q8 -> -10 | S8: 60236 | T8: 19 | U8: 15 | V8: ='Clean Data PL'!U8/'Clean Data PL'!T8 -> 0.78947368 | W8: 2.47 | X8: 32 | Y8: 30 | Z8: =X8-Y8 -> 2
B9: Brighton | C9: 30426 | D9: 19 | E9: 6 | F9: ='Clean Data PL'!E9/'Clean Data PL'!D9 -> 0.31578947 | G9: 1.21 | H9: -9 | I9: -16 | J9: =H9-I9 -> 7 | K9: 523 | L9: 19 | M9: 4 | N9: ='Clean Data PL'!M9/'Clean Data PL'!L9 -> 0.21052632 | O9: 1.11 | P9: 0 | Q9: -6 | R9: =P9-Q9 -> 6 | S9: 32638 | T9: 19 | U9: 8 | V9: ='Clean Data PL'!U9/'Clean Data PL'!T9 -> 0.42105263 | W9: 1.58 | X9: 3 | Y9: -10 | Z9: =X9-Y9 -> 13
B10: Burnley | C10: 20534 | D10: 19 | E10: 7 | F10: ='Clean Data PL'!E10/'Clean Data PL'!D10 -> 0.36842105 | G10: 1.21 | H10: -8 | I10: -15 | J10: =H10-I10 -> 7 | K10: 178 | L10: 19 | M10: 4 | N10: ='Clean Data PL'!M10/'Clean Data PL'!L10 -> 0.21052632 | O10: 0.95 | P10: -13 | Q10: -9 | R10: =P10-Q10 -> -4 | S10: 21184 | T10: 19 | U10: 2 | V10: ='Clean Data PL'!U10/'Clean Data PL'!T10 -> 0.10526316 | W10: 0.53 | X10: -24 | Y10: -13 | Z10: =X10-Y10 -> -11
B11: Chelsea | C11: 40437 | D11: 19 | E11: 12 | F11: ='Clean Data PL'!E11/'Clean Data PL'!D11 -> 0.63157895 | G11: 2.21 | H11: 27 | I11: -3 | J11: =H11-I11 -> 30 | K11: 526 | L11: 19 | M11: 9 | N11: ='Clean Data PL'!M11/'Clean Data PL'!L11 -> 0.47368421 | O11: 1.74 | P11: 13 | Q11: 9 | R11: =P11-Q11 -> 4 | S11: 39524 | T11: 19 | U11: 11 | V11: ='Clean Data PL'!U11/'Clean Data PL'!T11 -> 0.57894737 | W11: 1.95 | X11: 18 | Y11: -4 | Z11: =X11-Y11 -> 22
B12: Crystal Palace | C12: 25455 | D12: 19 | E12: 5 | F12: ='Clean Data PL'!E12/'Clean Data PL'!D12 -> 0.26315789 | G12: 1.05 | H12: -4 | I12: 2 | J12: =H12-I12 -> -6 | K12: 447 | L12: 19 | M12: 6 | N12: ='Clean Data PL'!M12/'Clean Data PL'!L12 -> 0.31578947 | O12: 1.21 | P12: -12 | Q12: -13 | R12: =P12-Q12 -> 1 | S12: 24932 | T12: 19 | U12: 8 | V12: ='Clean Data PL'!U12/'Clean Data PL'!T12 -> 0.42105263 | W12: 1.47 | X12: 11 | Y12: -12 | Z12: =X12-Y12 -> 23
B13: Everton | C13: 39043 | D13: 19 | E13: 10 | F13: ='Clean Data PL'!E13/'Clean Data PL'!D13 -> 0.52631579 | G13: 1.79 | H13: 9 | I13: -1 | J13: =H13-I13 -> 10 | K13: 368 | L13: 19 | M13: 6 | N13: ='Clean Data PL'!M13/'Clean Data PL'!L13 -> 0.31578947 | O13: 1.16 | P13: -4 | Q13: 3 | R13: =P13-Q13 -> -7 | S13: 39042 | T13: 19 | U13: 8 | V13: ='Clean Data PL'!U13/'Clean Data PL'!T13 -> 0.42105263 | W13: 1.47 | X13: 4 | Y13: -15 | Z13: =X13-Y13 -> 19
B14: Fulham | C14: 24371 | D14: 19 | E14: 6 | F14: ='Clean Data PL'!E14/'Clean Data PL'!D14 -> 0.31578947 | G14: 1.11 | H14: -14 | I14: -33 | J14: =H14-I14 -> 19 | K14: 211 | L14: 19 | M14: 2 | N14: ='Clean Data PL'!M14/'Clean Data PL'!L14 -> 0.10526316 | O14: 0.53 | P14: -19 | Q14: -7 | R14: =P14-Q14 -> -12 | S14: 24302 | T14: 19 | U14: 9 | V14: ='Clean Data PL'!U14/'Clean Data PL'!T14 -> 0.47368421 | W14: 1.53 | X14: 7 | Y14: -13 | Z14: =X14-Y14 -> 20
B15: Liverpool | C15: 52983 | D15: 19 | E15: 17 | F15: ='Clean Data PL'!E15/'Clean Data PL'!D15 -> 0.89473684 | G15: 2.79 | H15: 45 | I15: 22 | J15: =H15-I15 -> 23 | K15: 837 | L15: 19 | M15: 10 | N15: ='Clean Data PL'!M15/'Clean Data PL'!L15 -> 0.52631579 | O15: 1.74 | P15: 9 | Q15: 17 | R15: =P15-Q15 -> -8 | S15: 55979 | T15: 19 | U15: 15 | V15: ='Clean Data PL'!U15/'Clean Data PL'!T15 -> 0.78947368 | W15: 2.53 | X15: 32 | Y15: 13 | Z15: =X15-Y15 -> 19
B16: Manchester City | C16: 54130 | D16: 19 | E16: 18 | F16: ='Clean Data PL'!E16/'Clean Data PL'!D16 -> 0.94736842 | G16: 2.84 | H16: 45 | I16: 27 | J16: =H16-I16 -> 18 | K16: 526 | L16: 19 | M16: 13 | N16: ='Clean Data PL'!M16/'Clean Data PL'!L16 -> 0.68421053 | O16: 2.16 | P16: 26 | Q16: 25 | R16: =P16-Q16 -> 1 | S16: 53012 | T16: 19 | U16: 14 | V16: ='Clean Data PL'!U16/'Clean Data PL'!T16 -> 0.73684211 | W16: 2.47 | X16: 35 | Y16: 27 | Z16: =X16-Y16 -> 8
B17: Manchester Utd | C17: 74498 | D17: 19 | E17: 10 | F17: ='Clean Data PL'!E17/'Clean Data PL'!D17 -> 0.52631579 | G17: 1.89 | H17: 8 | I17: 3 | J17: =H17-I17 -> 5 | K17: 526 | L17: 19 | M17: 9 | N17: ='Clean Data PL'!M17/'Clean Data PL'!L17 -> 0.47368421 | O17: 1.63 | P17: 10 | Q17: 19 | R17: =P17-Q17 -> -9 | S17: 73533 | T17: 19 | U17: 10 | V17: ='Clean Data PL'!U17/'Clean Data PL'!T17 -> 0.52631579 | W17: 1.74 | X17: 3 | Y17: -4 | Z17: =X17-Y17 -> 7
B18: Newcastle Utd | C18: 51121 | D18: 19 | E18: 8 | F18: ='Clean Data PL'!E18/'Clean Data PL'!D18 -> 0.42105263 | G18: 1.32 | H18: -1 | I18: -5 | J18: =H18-I18 -> 4 | K18: 526 | L18: 19 | M18: 6 | N18: ='Clean Data PL'!M18/'Clean Data PL'!L18 -> 0.31578947 | O18: 1.21 | P18: -7 | Q18: -9 | R18: =P18-Q18 -> 2 | S18: 52125 | T18: 19 | U18: 12 | V18: ='Clean Data PL'!U18/'Clean Data PL'!T18 -> 0.63157895 | W18: 2.11 | X18: 27 | Y18: -4 | Z18: =X18-Y18 -> 31
B19: Tottenham | C19: 54216 | D19: 19 | E19: 12 | F19: ='Clean Data PL'!E19/'Clean Data PL'!D19 -> 0.63157895 | G19: 2 | H19: 18 | I19: 10 | J19: =H19-I19 -> 8 | K19: 632 | L19: 19 | M19: 10 | N19: ='Clean Data PL'!M19/'Clean Data PL'!L19 -> 0.52631579 | O19: 1.74 | P19: 15 | Q19: 8 | R19: =P19-Q19 -> 7 | S19: 61482 | T19: 19 | U19: 13 | V19: ='Clean Data PL'!U19/'Clean Data PL'!T19 -> 0.68421053 | W19: 2.05 | X19: 11 | Y19: 2 | Z19: =X19-Y19 -> 9
... B21: Wolves | C21: 31030 | D21: 19 | E21: 10 | F21: ='Clean Data PL'!E21/'Clean Data PL'!D21 -> 0.52631579 | G21: 1.79 | H21: 7 | I21: -6 | J21: =H21-I21 -> 13 | K21: 237 | L21: 19 | M21: 7 | N21: ='Clean Data PL'!M21/'Clean Data PL'!L21 -> 0.36842105 | O21: 1.32 | P21: -4 | Q21: -12 | R21: =P21-Q21 -> 8 | S21: 31029 | T21: 19 | U21: 8 | V21: ='Clean Data PL'!U21/'Clean Data PL'!T21 -> 0.42105263 | W21: 1.42 | X21: -4 | Y21: -11 | Z21: =X21-Y21 -> 7
B26: *all 20 teams per season
B28: 2018-19 | C28: Squad | D28: Attendance | E28: MP | F28: W | G28: WP | H28: Pts/MP | I28: Home GD | J28: Away GD | K28: PG
C29: Arsenal | D29: 59899 | E29: 19 | F29: 14 | G29: ='Clean Data PL'!F29/'Clean Data PL'!E29 -> 0.73684211 | H29: 2.37 | I29: 26 | J29: -4 | K29: =I29-J29 -> 30
C30: Bournemouth | D30: 10532 | E30: 19 | F30: 8 | G30: ='Clean Data PL'!F30/'Clean Data PL'!E30 -> 0.42105263 | H30: 1.53 | I30: 5 | J30: -19 | K30: =I30-J30 -> 24
C31: Brighton | D31: 30426 | E31: 19 | F31: 6 | G31: ='Clean Data PL'!F31/'Clean Data PL'!E31 -> 0.31578947 | H31: 1.21 | I31: -9 | J31: -16 | K31: =I31-J31 -> 7
C32: Burnley | D32: 20534 | E32: 19 | F32: 7 | G32: ='Clean Data PL'!F32/'Clean Data PL'!E32 -> 0.36842105 | H32: 1.21 | I32: -8 | J32: -15 | K32: =I32-J32 -> 7
C33: Cardiff City | D33: 31408 | E33: 19 | F33: 6 | G33: ='Clean Data PL'!F33/'Clean Data PL'!E33 -> 0.31578947 | H33: 1.05 | I33: -17 | J33: -18 | K33: =I33-J33 -> 1
C34: Chelsea | D34: 40437 | E34: 19 | F34: 12 | G34: ='Clean Data PL'!F34/'Clean Data PL'!E34 -> 0.63157895 | H34: 2.21 | I34: 27 | J34: -3 | K34: =I34-J34 -> 30
C35: Crystal Palace | D35: 25455 | E35: 19 | F35: 5 | G35: ='Clean Data PL'!F35/'Clean Data PL'!E35 -> 0.26315789 | H35: 1.05 | I35: -4 | J35: 2 | K35: =I35-J35 -> -6
C36: Everton | D36: 39043 | E36: 19 | F36: 10 | G36: ='Clean Data PL'!F36/'Clean Data PL'!E36 -> 0.52631579 | H36: 1.79 | I36: 9 | J36: -1 | K36: =I36-J36 -> 10
C37: Fulham | D37: 24371 | E37: 19 | F37: 6 | G37: ='Clean Data PL'!F37/'Clean Data PL'!E37 -> 0.31578947 | H37: 1.11 | I37: -14 | J37: -33 | K37: =I37-J37 -> 19
C38: Huddersfield | D38: 23203 | E38: 19 | F38: 2 | G38: ='Clean Data PL'!F38/'Clean Data PL'!E38 -> 0.10526316 | H38: 0.47 | I38: -21 | J38: -33 | K38: =I38-J38 -> 12
C39: Leicester City | D39: 31851 | E39: 19 | F39: 8 | G39: ='Clean Data PL'!F39/'Clean Data PL'!E39 -> 0.42105263 | H39: 1.42 | I39: 4 | J39: -1 | K39: =I39-J39 -> 5
C40: Liverpool | D40: 52983 | E40: 19 | F40: 17 | G40: ='Clean Data PL'!F40/'Clean Data PL'!E40 -> 0.89473684 | H40: 2.79 | I40: 45 | J40: 22 | K40: =I40-J40 -> 23
... C48: Wolves | D48: 31030 | E48: 19 | F48: 10 | G48: ='Clean Data PL'!F48/'Clean Data PL'!E48 -> 0.52631579 | H48: 1.79 | I48: 7 | J48: -6 | K48: =I48-J48 -> 13
B50: 2020-21 | C50: Squad | D50: Attendance | E50: MP | F50: W | G50: WP | H50: Pts/MP | I50: Home GD | J50: Away GD | K50: PG
C51: Arsenal | D51: 632 | E51: 19 | F51: 8 | G51: ='Clean Data PL'!F51/'Clean Data PL'!E51 -> 0.42105263 | H51: 1.47 | I51: 3 | J51: 13 | K51: =I51-J51 -> -10
C52: Aston Villa | D52: 526 | E52: 19 | F52: 7 | G52: ='Clean Data PL'!F52/'Clean Data PL'!E52 -> 0.36842105 | H52: 1.32 | I52: 2 | J52: 7 | K52: =I52-J52 -> -5
C53: Brighton | D53: 523 | E53: 19 | F53: 4 | G53: ='Clean Data PL'!F53/'Clean Data PL'!E53 -> 0.21052632 | H53: 1.11 | I53: 0 | J53: -6 | K53: =I53-J53 -> 6
C54: Burnley | D54: 178 | E54: 19 | F54: 4 | G54: ='Clean Data PL'!F54/'Clean Data PL'!E54 -> 0.21052632 | H54: 0.95 | I54: -13 | J54: -9 | K54: =I54-J54 -> -4
C55: Chelsea | D55: 526 | E55: 19 | F55: 9 | G55: ='Clean Data PL'!F55/'Clean Data PL'!E55 -> 0.47368421 | H55: 1.74 | I55: 13 | J55: 9 | K55: =I55-J55 -> 4
C56: Crystal Palace | D56: 447 | E56: 19 | F56: 6 | G56: ='Clean Data PL'!F56/'Clean Data PL'!E56 -> 0.31578947 | H56: 1.21 | I56: -12 | J56: -13 | K56: =I56-J56 -> 1
C57: Everton | D57: 368 | E57: 19 | F57: 6 | G57: ='Clean Data PL'!F57/'Clean Data PL'!E57 -> 0.31578947 | H57: 1.16 | I57: -4 | J57: 3 | K57: =I57-J57 -> -7
...

Sheet Data Dictionary
B2: DATA DICTIONARY
B4: Features | C4: Description | D4: Range
B5: Squad | C5: team name | D5: All Premier League or La Liga team names
B6: Attendance | C6: Attendance/Game: home attendance per game during that season | D6: (91, 76104)
B7: MP | C7: Matches Played: total home games played by the team that season | D7: 19
B8: W | C8: Wins: total home wins by the team that season | D8: (2, 18)
B9: WP | C9: Win Percentage: how often the team won at home that season (home wins ÷ total home games) | D9: (5.26%, 94.74%)
B10: Pts/MP | C10: Points/Match: home points earned per home games played that season (3 for win, 1 for draw, 0 for loss) | D10: (.47, 2.84)
B11: Home GD | C11: Home Goal Difference: goals a team scores at home vs. concedes (home goals for - home goals against) | D11: (-38, 45)
B12: Away GD | C12: Away Goal Difference: goals a team scores away vs. concedes (away goals for - away goals against) | D12: (-33, 30)
B13: PG | C13: Performance Gap: how much better teams play at home vs away (home goal differential - away goal differential) | D13: (-11, 31)
